Workbook

Sheet XCAL Clients Feeded
I1: =SUM(I3:I103213) -> 925250 | J1: =SUM(J3:J103213) -> 925250 | K1: =SUM(K3:K103213) -> 0
A2: M ID | B2: Member Name | C2: Payment Received Date | D2: Pacakage Start Date | E2: Pacakage End Date | F2: Month Of | G2: Days | H2: Pacakge | I2: Amount | J2: Total Cash | K2: Balance
A3: 1 | B3: Ovais Gigi | C3: 43902 | D3: 43899 | E3: =D3+G3-1 -> 43912 | F3: 43891 | G3: =INDEX('XCAL Packages'!B:B,MATCH(H3,'XCAL Packages'!A:A,FALSE),1) -> 14 | H3: Premium 14 days | I3: 28000 | J3: 28000 | K3: =I3-J3 -> 0
A4: 3 | B4: Mohammad Afzal Ilyas Gigi | C4: 43904 | D4: 43899 | E4: =D4+G4-1 -> 43912 | F4: 43891 | G4: =INDEX('XCAL Packages'!B:B,MATCH(H4,'XCAL Packages'!A:A,FALSE),1) -> 14 | H4: Premium 14 days | I4: 28000 | J4: 28000 | K4: =I4-J4 -> 0
A5: 2 | B5: Ahsan Gigi | C5: 43904 | D5: 43900 | E5: =D5+G5-1 -> 43913 | F5: 43891 | G5: =INDEX('XCAL Packages'!B:B,MATCH(H5,'XCAL Packages'!A:A,FALSE),1) -> 14 | H5: Premium 14 days | I5: 28000 | J5: 28000 | K5: =I5-J5 -> 0
A6: 4 | B6: Nabil Jangda | C6: 43903 | D6: 43901 | E6: =D6+G6-1 -> 43907 | F6: 43891 | G6: =INDEX('XCAL Packages'!B:B,MATCH(H6,'XCAL Packages'!A:A,FALSE),1) -> 7 | H6: Premium 7 days | I6: 14000 | J6: 14000 | K6: =I6-J6 -> 0
A7: 1 | B7: Ovais Gigi | C7: 43983 | D7: 43984 | E7: =D7+G7-1 -> 43997 | F7: 43983 | G7: =INDEX('XCAL Packages'!B:B,MATCH(H7,'XCAL Packages'!A:A,FALSE),1) -> 14 | H7: Premium 14 days | I7: 28000 | J7: 28000 | K7: =I7-J7 -> 0
A8: 2 | B8: Ahsan Gigi | C8: 43987 | D8: 43984 | E8: =D8+G8-1 -> 44013 | F8: 43983 | G8: =INDEX('XCAL Packages'!B:B,MATCH(H8,'XCAL Packages'!A:A,FALSE),1) -> 30 | H8: Premium 30 days | I8: 56000 | J8: 56000 | K8: =I8-J8 -> 0
A9: 3 | B9: Mohammed Afzal Ilyas Gigi | C9: 43987 | D9: 43984 | E9: =D9+G9-1 -> 44013 | F9: 43983 | G9: =INDEX('XCAL Packages'!B:B,MATCH(H9,'XCAL Packages'!A:A,FALSE),1) -> 30 | H9: Premium 30 days | I9: 56000 | J9: 56000 | K9: =I9-J9 -> 0
A10: 6 | B10: Uzma Sattar | C10: 43986 | D10: 43984 | E10: =D10+G10-1 -> 43990 | F10: 43983 | G10: =INDEX('XCAL Packages'!B:B,MATCH(H10,'XCAL Packages'!A:A,FALSE),1) -> 7 | H10: Traditional 7 days | I10: 8000 | J10: 8000 | K10: =I10-J10 -> 0
A11: 10 | B11: Usman Yunus Ghani | C11: 43986 | D11: 43984 | E11: =D11+G11-1 -> 43990 | F11: 43983 | G11: =INDEX('XCAL Packages'!B:B,MATCH(H11,'XCAL Packages'!A:A,FALSE),1) -> 7 | H11: Premium 7 days | I11: 10500 | J11: 10500 | K11: =I11-J11 -> 0
A12: 11 | B12: Mohammad Ilyas Gigi | C12: 43987 | D12: 43984 | E12: =D12+G12-1 -> 43997 | F12: 43983 | G12: =INDEX('XCAL Packages'!B:B,MATCH(H12,'XCAL Packages'!A:A,FALSE),1) -> 14 | H12: Traditional 14 days | I12: 20000 | J12: 20000 | K12: =I12-J12 -> 0
A13: 12 | B13: Nida Afzal | C13: 43987 | D13: 43984 | E13: =D13+G13-1 -> 44013 | F13: 43983 | G13: =INDEX('XCAL Packages'!B:B,MATCH(H13,'XCAL Packages'!A:A,FALSE),1) -> 30 | H13: Premium 30 days | I13: 56000 | J13: 56000 | K13: =I13-J13 -> 0
A14: 13 | B14: Arikah Usman Ghani | C14: 43986 | D14: 43984 | E14: =D14+G14-1 -> 43990 | F14: 43983 | G14: =INDEX('XCAL Packages'!B:B,MATCH(H14,'XCAL Packages'!A:A,FALSE),1) -> 7 | H14: Traditional 7 days | I14: 7500 | J14: 7500 | K14: =I14-J14 -> 0
... A62: 25 | B62: Sameer Ahmedani | C62: 44061 | D62: 44050 | E62: =D62+G62-1 -> 44056 | F62: 44044 | G62: =INDEX('XCAL Packages'!B:B,MATCH(H62,'XCAL Packages'!A:A,FALSE),1) -> 7 | H62: Traditional 7 days | I62: 10000 | J62: 10000 | K62: =I62-J62 -> 0

Sheet XCAL Packages
A1: Pacakge | B1: Days | C1: Amount
A2: Premium 30 days | B2: 30 | C2: 56000
A3: Premium 21 days | B3: 21 | C3: 42000
A4: Premium 14 days | B4: 14 | C4: 28000
A5: Premium 7 days | B5: 7 | C5: 14000
A6: Traditional 30 days | B6: 30 | C6: 39500
A7: Traditional 21 days | B7: 21 | C7: 30000
A8: Traditional 14 days | B8: 14 | C8: 20000
A9: Traditional 7 days | B9: 7 | C9: 10000
A10: Premium 30 days - Dinner | B10: 30 | C10: 18000
A11: Premium 21 days - Dinner | B11: 21 | C11: 15000
A12: Premium 14 days - Dinner | B12: 14 | C12: 10000
A13: Premium 7 days - Dinner | B13: 7 | C13: 5000
... A44: Traditional 1 day | B44: 1 | C44: 1500

Sheet Misc Revenue
C1: =SUM(C3:C111003) -> 0 | D1: =SUM(D3:D111003) -> 0 | E1: =SUM(E3:E111003) -> 0
A2: Invoice Date | B2: Item | C2: Amount | D2: Total Cash | E2: Balance
E3: =C3-D3 -> 0
E4: =C4-D4 -> 0
E5: =C5-D5 -> 0
E6: =C6-D6 -> 0
E7: =C7-D7 -> 0
E8: =C8-D8 -> 0
E9: =C9-D9 -> 0
E10: =C10-D10 -> 0

Sheet Total Sales
B1: Monthly | C1: Cash | D1: Total | E1: Balance
A2: XCAL Sale Feeded | B2: ='XCAL Clients Feeded'!I1 -> 925250 | C2: ='XCAL Clients Feeded'!J1 -> 925250 | D2: =C2 -> 925250 | E2: ='XCAL Clients Feeded'!K1 -> 0
A3: Misc Sale | C3: ='Misc Revenue'!D1 -> 0 | D3: =C3 -> 0 | E3: ='Misc Revenue'!E1 -> 0
A4: Balance in Software | C4: =SUM(C2:C3) -> 925250 | D4: =C4 -> 925250 | E4: =SUM(E2:E3) -> 0
C7: 925250
C8: =C4-C7 -> 0

Sheet Expenses
A1: Date | B1: Month of | C1: Off / Unoff | D1: Type | E1: Account | F1: Particulars | G1: Amount | I1: =SUM(G2:G107395) -> 3240250 | K1: Paid from VX | L1: =SUM(H2:H153) -> 1079601
A2: 7-Oct-2019 | B2: 43678 | C2: Unofficial | D2: Kitchen Equipments | E2: XCAL Account | F2: Kitchen Equipments & Installation Charges - Advance - Paid to Raj Hotel Equipments - Inv# RHE515253 | G2: 200000
A3: 7-Oct-2019 | B3: 43709 | C3: Unofficial | D3: Kitchen Equipments | E3: XCAL Account | F3: Kitchen Equipments & Installation Charges - Advance - Paid to Raj Hotel Equipments - Inv# RHE515253 | G3: 300000
A4: 10-Oct-2019 | B4: 43709 | C4: Unofficial | D4: Kitchen | E4: XCAL Account | F4: Consultancy Charges - Advance - Paid to Kevin | G4: 50000
A5: 9-Nov-2019 | B5: 43739 | C5: Unofficial | D5: Kitchen Equipments | E5: XCAL Account | F5: Kitchen Equipments & Installation Charges-2nd Payment - Paid to Raj Hotel Equipments-Inv# RHE515253 | G5: 200000
A6: 3-Dec-2019 | B6: 43739 | C6: Unofficial | D6: Construction | E6: XCAL Account | F6: Construction Cash | G6: 274054
A7: 11-Dec-2019 | B7: 43739 | C7: Unofficial | D7: Kitchen Equipments | E7: XCAL Account | F7: Purchase Kitchen Utensils | G7: 57000
A8: 19-Dec-2019 | B8: 43739 | C8: Unofficial | D8: Kitchen | E8: XCAL Account | F8: Consultancy Charges - 2nd Installment Part Payment - Paid to Kevin | G8: 20000
A9: 24-Dec-2019 | B9: 43770 | C9: Unofficial | D9: Kitchen | E9: XCAL Account | F9: Packaging Accessories | G9: 2000
A10: 26-Dec-2019 | B10: 43770 | C10: Unofficial | D10: Construction | E10: XCAL Account | F10: Paint and Polish Work - Paid to Imran Shams | G10: 75000
A11: 4-Jan-2020 | B11: 43770 | C11: Unofficial | D11: Construction | E11: XCAL Account | F11: Construction Cash | G11: 18900
A12: 17-Jan-2020 | B12: 43770 | C12: Unofficial | D12: Kitchen Equipments | E12: XCAL Account | F12: Kitchen Equipments & Installation Charges-3rd Payment - Paid to Raj Hotel Equipments-Inv# RHE515253 | G12: 100000
A13: 17-Jan-2020 | B13: 43831 | C13: Unofficial | D13: XCAL Food Purchase | E13: XCAL Account | F13: Purchase Food Material - Paid to Kevin | G13: 35000
... A49: 3-Mar-2020 | B49: 43862 | C49: Unofficial | D49: XCAL Food Purchase | E49: XCAL Account | F49: Purchase Food Material - Paid to Kashif Seasonal Fresh against Inv# 411-27022020 | G49: 3020
A50: 3-Mar-2020 | B50: 43862 | C50: Unofficial | D50: XCAL Food Purchase | E50: XCAL Account | F50: Purchase Food Material - Paid to Kashif Seasonal Fresh against Inv# 410-25022020 | G50: 8038 | H50: 855
A51: 2-Mar-2020 | B51: 43862 | C51: Unofficial | D51: Petty Cash | E51: XCAL Account | F51: Kitchen Petty Cash | H51: 70772
A52: 4-Mar-2020 | B52: 43862 | C52: Unofficial | D52: Salary | E52: XCAL Account | F52: February Salary - No Absent Salary (XCAL - Persons) | H52: 6000
A53: 5-Mar-2020 | B53: 43862 | C53: Unofficial | D53: Utility | E53: XCAL Account | F53: Gas Bill | H53: 12830
A54: 7-Mar-2020 | B54: 43831 | C54: Unofficial | D54: Kitchen Equipments | E54: XCAL Account | F54: Philips Air Fryer HD-9220 Purchase for XCAL | H54: 25800
A55: 10-Mar-2020 | B55: 43831 | C55: Unofficial | D55: Marketing | E55: XCAL Account | F55: Photography - XCAL | H55: 35000
A56: 10-Mar-2020 | B56: 43891 | C56: Unofficial | D56: XCAL Food Purchase | E56: XCAL Account | F56: Purchase Food Material - Paid to Kashif Seasonal Fresh against Inv# 905-05032020 | H56: 1960
A57: 10-Mar-2020 | B57: 43891 | C57: Unofficial | D57: XCAL Food Purchase | E57: XCAL Account | F57: Purchase Food Material - Paid to Kashif Seasonal Fresh against Inv# 904-04032020 | H57: 1415
A58: 10-Mar-2020 | B58: 43891 | C58: Unofficial | D58: XCAL Food Purchase | E58: XCAL Account | F58: Purchase Food Material - Paid to Kashif Seasonal Fresh against Inv# 902-03032020 | H58: 7780
A59: 11-Mar-2020 | B59: 43862 | C59: Unofficial | D59: Salary | E59: XCAL Account | F59: February Salary - Fiza Zahid (XCAL) | H59: 15000
A60: 12-Mar-2020 | B60: 43831 | C60: Unofficial | D60: Construction | E60: XCAL Account | F60: Wall Rack & Table Counter with Drawer Charges for XCAL - Paid to A.M. Traders | H60: 50000
A61: 13-Mar-2020 | B61: 43831 | C61: Unofficial | D61: Marketing | E61: XCAL Account | F61: XCAL Round Sticker-6000 Pcs & Rectangle Sticker-6200 Pcs - Paid to Habib Wakeel against Inv# C 3686 | H61: 10960
A62: 13-Mar-2020 | B62: 43831 | C62: Unofficial | D62: Marketing | E62: XCAL Account | F62: XCAL Standee - 2 Standees - Paid to Habib Wakeel against Inv# C 3687 | H62: 2600
... A85: 16-May-2020 | B85: 43922 | C85: Unofficial | D85: Misc | E85: XCAL Account | F85: XCAL Mobile Bill# 03212502600 | H85: 807
A86: 43831 | B86: 43831 | C86: Unofficial | D86: Rent | E86: XCAL Account | F86: Rent January 2020 | H86: 50000
A87: 43862 | B87: 43862 | C87: Unofficial | D87: Rent | E87: XCAL Account | F87: Rent February 2020 | H87: 50000
A88: 43891 | B88: 43891 | C88: Unofficial | D88: Rent | E88: XCAL Account | F88: Rent March 2020 | H88: 50000
A89: 43922 | B89: 43922 | C89: Unofficial | D89: Rent | E89: XCAL Account | F89: Rent April 2020 | H89: 50000
A90: 43891 | B90: 43891 | C90: Unofficial | D90: Utility | E90: XCAL Account | F90: K Electric Bill | H90: 50000
A91: 43922 | B91: 43922 | C91: Unofficial | D91: Utility | E91: XCAL Account | F91: K Electric Bill | H91: 50000
A92: 43985 | B92: 43952 | C92: Unofficial | D92: Utility | E92: XCAL Account | F92: Gas Bill | G92: 2930
A93: 43987 | B93: 43952 | C93: Unofficial | D93: Salary | E93: XCAL Account | F93: 20087 - May Salary - Kevin Joseph (XCAL - Chef) | G93: 40000
A94: 43987 | B94: 43952 | C94: Unofficial | D94: Salary | E94: XCAL Account | F94: 20088 - May Salary - Muslim (XCAL - Assistant Chef) | G94: 20000
A95: 43987 | B95: 43952 | C95: Unofficial | D95: Salary | E95: XCAL Account | F95: 20089 - May Salary - Nihal Kumar (XCAL - Dishwasher) | G95: 17600
A96: 43987 | B96: 43952 | C96: Unofficial | D96: Salary | E96: XCAL Account | F96: 20090 - May Salary - Kevin Bobby Samuel (XCAL - Helper) | G96: 18400
A97: 43991 | B97: 43983 | C97: Unofficial | D97: Misc | E97: XCAL Account | F97: Bracket Fan | G97: 4200
...

Sheet Expense Breakup
A1: Total | B1: Unofficial | C1: 43678 | D1: 43709 | E1: 43739 | F1: 43770 | G1: 43800 | H1: 43831 | I1: 43862 | J1: 43891 | K1: 43922 | L1: 43952 | M1: 43983 | N1: 44013 | O1: 44044 | P1: 44075 | Q1: 44105 | R1: 44136 | S1: 44166
A2: =SUM(C2:AA2) -> 115870 | B2: Utility | C2: =SUMIFS(Expenses!$G:$G,Expenses!$B:$B,$C$1,Expenses!$D:$D,$B$2,Expenses!$C:$C,$B$1) -> 0 | D2: =SUMIFS(Expenses!$G:$G,Expenses!$B:$B,$D$1,Expenses!$D:$D,B2,Expenses!$C:$C,$B$1) -> 0 | E2: =SUMIFS(Expenses!$G:$G,Expenses!$B:$B,$E$1,Expenses!$D:$D,B2,Expenses!$C:$C,$B$1) -> 0 | F2: =SUMIFS(Expenses!$G:$G,Expenses!$B:$B,$F$1,Expenses!$D:$D,B2,Expenses!$C:$C,$B$1) -> 0 | G2: =SUMIFS(Expenses!$G:$G,Expenses!$B:$B,$G$1,Expenses!$D:$D,B2,Expenses!$C:$C,$B$1) -> 0 | H2: =SUMIFS(Expenses!$G:$G,Expenses!$B:$B,$H$1,Expenses!$D:$D,B2,Expenses!$C:$C,$B$1) -> 0 | I2: =SUMIFS(Expenses!$G:$G,Expenses!$B:$B,$I$1,Expenses!$D:$D,B2,Expenses!$C:$C,$B$1) -> 0 | J2: =SUMIFS(Expenses!$G:$G,Expenses!$B:$B,$J$1,Expenses!$D:$D,B2,Expenses!$C:$C,$B$1) -> 0 | K2: =SUMIFS(Expenses!$G:$G,Expenses!$B:$B,$K$1,Expenses!$D:$D,B2,Expenses!$C:$C,$B$1) -> 0 | L2: =SUMIFS(Expenses!$G:$G,Expenses!$B:$B,$L$1,Expenses!$D:$D,B2,Expenses!$C:$C,$B$1) -> 52930 | M2: =SUMIFS(Expenses!$G:$G,Expenses!$B:$B,$M$1,Expenses!$D:$D,B2,Expenses!$C:$C,$B$1) -> 55410 | N2: =SUMIFS(Expenses!$G:$G,Expenses!$B:$B,$N$1,Expenses!$D:$D,B2,Expenses!$C:$C,$B$1) -> 7530 | O2: =SUMIFS(Expenses!$G:$G,Expenses!$B:$B,$O$1,Expenses!$D:$D,B2,Expenses!$C:$C,$B$1) -> 0 | P2: =SUMIFS(Expenses!$G:$G,Expenses!$B:$B,$P$1,Expenses!$D:$D,B2,Expenses!$C:$C,$B$1) -> 0 | Q2: =SUMIFS(Expenses!$G:$G,Expenses!$B:$B,$Q$1,Expenses!$D:$D,B2,Expenses!$C:$C,$B$1) -> 0 | R2: =SUMIFS(Expenses!$G:$G,Expenses!$B:$B,$R$1,Expenses!$D:$D,B2,Expenses!$C:$C,$B$1) -> 0 | S2: =SUMIFS(Expenses!$G:$G,Expenses!$B:$B,$S$1,Expenses!$D:$D,B2,Expenses!$C:$C,$B$1) -> 0
A3: =SUM(C3:AA3) -> 25368 | B3: Accessories | C3: =SUMIFS(Expenses!$G:$G,Expenses!$B:$B,$C$1,Expenses!$D:$D,B3,Expenses!$C:$C,$B$1) -> 0 | D3: =SUMIFS(Expenses!$G:$G,Expenses!$B:$B,$D$1,Expenses!$D:$D,B3,Expenses!$C:$C,$B$1) -> 0 | E3: =SUMIFS(Expenses!$G:$G,Expenses!$B:$B,$E$1,Expenses!$D:$D,B3,Expenses!$C:$C,$B$1) -> 0 | F3: =SUMIFS(Expenses!$G:$G,Expenses!$B:$B,$F$1,Expenses!$D:$D,B3,Expenses!$C:$C,$B$1) -> 0 | G3: =SUMIFS(Expenses!$G:$G,Expenses!$B:$B,$G$1,Expenses!$D:$D,B3,Expenses!$C:$C,$B$1) -> 0 | H3: =SUMIFS(Expenses!$G:$G,Expenses!$B:$B,$H$1,Expenses!$D:$D,B3,Expenses!$C:$C,$B$1) -> 25368 | I3: =SUMIFS(Expenses!$G:$G,Expenses!$B:$B,$I$1,Expenses!$D:$D,B3,Expenses!$C:$C,$B$1) -> 0 | J3: =SUMIFS(Expenses!$G:$G,Expenses!$B:$B,$J$1,Expenses!$D:$D,B3,Expenses!$C:$C,$B$1) -> 0 | K3: =SUMIFS(Expenses!$G:$G,Expenses!$B:$B,$K$1,Expenses!$D:$D,B3,Expenses!$C:$C,$B$1) -> 0 | L3: =SUMIFS(Expenses!$G:$G,Expenses!$B:$B,$L$1,Expenses!$D:$D,B3,Expenses!$C:$C,$B$1) -> 0 | M3: =SUMIFS(Expenses!$G:$G,Expenses!$B:$B,$M$1,Expenses!$D:$D,B3,Expenses!$C:$C,$B$1) -> 0 | N3: =SUMIFS(Expenses!$G:$G,Expenses!$B:$B,$N$1,Expenses!$D:$D,B3,Expenses!$C:$C,$B$1) -> 0 | O3: =SUMIFS(Expenses!$G:$G,Expenses!$B:$B,$O$1,Expenses!$D:$D,B3,Expenses!$C:$C,$B$1) -> 0 | P3: =SUMIFS(Expenses!$G:$G,Expenses!$B:$B,$P$1,Expenses!$D:$D,B3,Expenses!$C:$C,$B$1) -> 0 | Q3: =SUMIFS(Expenses!$G:$G,Expenses!$B:$B,$Q$1,Expenses!$D:$D,B3,Expenses!$C:$C,$B$1) -> 0 | R3: =SUMIFS(Expenses!$G:$G,Expenses!$B:$B,$R$1,Expenses!$D:$D,B3,Expenses!$C:$C,$B$1) -> 0 | S3: =SUMIFS(Expenses!$G:$G,Expenses!$B:$B,$S$1,Expenses!$D:$D,B3,Expenses!$C:$C,$B$1) -> 0
A4: =SUM(C4:AA4) -> 152750 | B4: Marketing | C4: =SUMIFS(Expenses!$G:$G,Expenses!$B:$B,$C$1,Expenses!$D:$D,B4,Expenses!$C:$C,$B$1) -> 0 | D4: =SUMIFS(Expenses!$G:$G,Expenses!$B:$B,$D$1,Expenses!$D:$D,B4,Expenses!$C:$C,$B$1) -> 0 | E4: =SUMIFS(Expenses!$G:$G,Expenses!$B:$B,$E$1,Expenses!$D:$D,B4,Expenses!$C:$C,$B$1) -> 0 | F4: =SUMIFS(Expenses!$G:$G,Expenses!$B:$B,$F$1,Expenses!$D:$D,B4,Expenses!$C:$C,$B$1) -> 0 | G4: =SUMIFS(Expenses!$G:$G,Expenses!$B:$B,$G$1,Expenses!$D:$D,B4,Expenses!$C:$C,$B$1) -> 35000 | H4: =SUMIFS(Expenses!$G:$G,Expenses!$B:$B,$H$1,Expenses!$D:$D,B4,Expenses!$C:$C,$B$1) -> 35000 | I4: =SUMIFS(Expenses!$G:$G,Expenses!$B:$B,$I$1,Expenses!$D:$D,B4,Expenses!$C:$C,$B$1) -> 0 | J4: =SUMIFS(Expenses!$G:$G,Expenses!$B:$B,$J$1,Expenses!$D:$D,B4,Expenses!$C:$C,$B$1) -> 0 | K4: =SUMIFS(Expenses!$G:$G,Expenses!$B:$B,$K$1,Expenses!$D:$D,B4,Expenses!$C:$C,$B$1) -> 0 | L4: =SUMIFS(Expenses!$G:$G,Expenses!$B:$B,$L$1,Expenses!$D:$D,B4,Expenses!$C:$C,$B$1) -> 0 | M4: =SUMIFS(Expenses!$G:$G,Expenses!$B:$B,$M$1,Expenses!$D:$D,B4,Expenses!$C:$C,$B$1) -> 52750 | N4: =SUMIFS(Expenses!$G:$G,Expenses!$B:$B,$N$1,Expenses!$D:$D,B4,Expenses!$C:$C,$B$1) -> 15000 | O4: =SUMIFS(Expenses!$G:$G,Expenses!$B:$B,$O$1,Expenses!$D:$D,B4,Expenses!$C:$C,$B$1) -> 15000 | P4: =SUMIFS(Expenses!$G:$G,Expenses!$B:$B,$P$1,Expenses!$D:$D,B4,Expenses!$C:$C,$B$1) -> 0 | Q4: =SUMIFS(Expenses!$G:$G,Expenses!$B:$B,$Q$1,Expenses!$D:$D,B4,Expenses!$C:$C,$B$1) -> 0 | R4: =SUMIFS(Expenses!$G:$G,Expenses!$B:$B,$R$1,Expenses!$D:$D,B4,Expenses!$C:$C,$B$1) -> 0 | S4: =SUMIFS(Expenses!$G:$G,Expenses!$B:$B,$S$1,Expenses!$D:$D,B4,Expenses!$C:$C,$B$1) -> 0
A5: =SUM(C5:AA5) -> 450290 | B5: Petty Cash | C5: =SUMIFS(Expenses!$G:$G,Expenses!$B:$B,$C$1,Expenses!$D:$D,B5,Expenses!$C:$C,$B$1) -> 0 | D5: =SUMIFS(Expenses!$G:$G,Expenses!$B:$B,$D$1,Expenses!$D:$D,B5,Expenses!$C:$C,$B$1) -> 0 | E5: =SUMIFS(Expenses!$G:$G,Expenses!$B:$B,$E$1,Expenses!$D:$D,B5,Expenses!$C:$C,$B$1) -> 0 | F5: =SUMIFS(Expenses!$G:$G,Expenses!$B:$B,$F$1,Expenses!$D:$D,B5,Expenses!$C:$C,$B$1) -> 0 | G5: =SUMIFS(Expenses!$G:$G,Expenses!$B:$B,$G$1,Expenses!$D:$D,B5,Expenses!$C:$C,$B$1) -> 0 | H5: =SUMIFS(Expenses!$G:$G,Expenses!$B:$B,$H$1,Expenses!$D:$D,B5,Expenses!$C:$C,$B$1) -> 4900 | I5: =SUMIFS(Expenses!$G:$G,Expenses!$B:$B,$I$1,Expenses!$D:$D,B5,Expenses!$C:$C,$B$1) -> 0 | J5: =SUMIFS(Expenses!$G:$G,Expenses!$B:$B,$J$1,Expenses!$D:$D,B5,Expenses!$C:$C,$B$1) -> 0 | K5: =SUMIFS(Expenses!$G:$G,Expenses!$B:$B,$K$1,Expenses!$D:$D,B5,Expenses!$C:$C,$B$1) -> 0 | L5: =SUMIFS(Expenses!$G:$G,Expenses!$B:$B,$L$1,Expenses!$D:$D,B5,Expenses!$C:$C,$B$1) -> 0 | M5: =SUMIFS(Expenses!$G:$G,Expenses!$B:$B,$M$1,Expenses!$D:$D,B5,Expenses!$C:$C,$B$1) -> 245915 | N5: =SUMIFS(Expenses!$G:$G,Expenses!$B:$B,$N$1,Expenses!$D:$D,B5,Expenses!$C:$C,$B$1) -> 199475 | O5: =SUMIFS(Expenses!$G:$G,Expenses!$B:$B,$O$1,Expenses!$D:$D,B5,Expenses!$C:$C,$B$1) -> 0 | P5: =SUMIFS(Expenses!$G:$G,Expenses!$B:$B,$P$1,Expenses!$D:$D,B5,Expenses!$C:$C,$B$1) -> 0 | Q5: =SUMIFS(Expenses!$G:$G,Expenses!$B:$B,$Q$1,Expenses!$D:$D,B5,Expenses!$C:$C,$B$1) -> 0 | R5: =SUMIFS(Expenses!$G:$G,Expenses!$B:$B,$R$1,Expenses!$D:$D,B5,Expenses!$C:$C,$B$1) -> 0 | S5: =SUMIFS(Expenses!$G:$G,Expenses!$B:$B,$S$1,Expenses!$D:$D,B5,Expenses!$C:$C,$B$1) -> 0
A6: =SUM(C6:AA6) -> 367954 | B6: Construction | C6: =SUMIFS(Expenses!$G:$G,Expenses!$B:$B,$C$1,Expenses!$D:$D,B6,Expenses!$C:$C,$B$1) -> 0 | D6: =SUMIFS(Expenses!$G:$G,Expenses!$B:$B,$D$1,Expenses!$D:$D,B6,Expenses!$C:$C,$B$1) -> 0 | E6: =SUMIFS(Expenses!$G:$G,Expenses!$B:$B,$E$1,Expenses!$D:$D,B6,Expenses!$C:$C,$B$1) -> 274054 | F6: =SUMIFS(Expenses!$G:$G,Expenses!$B:$B,$F$1,Expenses!$D:$D,B6,Expenses!$C:$C,$B$1) -> 93900 | G6: =SUMIFS(Expenses!$G:$G,Expenses!$B:$B,$G$1,Expenses!$D:$D,B6,Expenses!$C:$C,$B$1) -> 0 | H6: =SUMIFS(Expenses!$G:$G,Expenses!$B:$B,$H$1,Expenses!$D:$D,B6,Expenses!$C:$C,$B$1) -> 0 | I6: =SUMIFS(Expenses!$G:$G,Expenses!$B:$B,$I$1,Expenses!$D:$D,B6,Expenses!$C:$C,$B$1) -> 0 | J6: =SUMIFS(Expenses!$G:$G,Expenses!$B:$B,$J$1,Expenses!$D:$D,B6,Expenses!$C:$C,$B$1) -> 0 | K6: =SUMIFS(Expenses!$G:$G,Expenses!$B:$B,$K$1,Expenses!$D:$D,B6,Expenses!$C:$C,$B$1) -> 0 | L6: =SUMIFS(Expenses!$G:$G,Expenses!$B:$B,$L$1,Expenses!$D:$D,B6,Expenses!$C:$C,$B$1) -> 0 | M6: =SUMIFS(Expenses!$G:$G,Expenses!$B:$B,$M$1,Expenses!$D:$D,B6,Expenses!$C:$C,$B$1) -> 0 | N6: =SUMIFS(Expenses!$G:$G,Expenses!$B:$B,$N$1,Expenses!$D:$D,B6,Expenses!$C:$C,$B$1) -> 0 | O6: =SUMIFS(Expenses!$G:$G,Expenses!$B:$B,$O$1,Expenses!$D:$D,B6,Expenses!$C:$C,$B$1) -> 0 | P6: =SUMIFS(Expenses!$G:$G,Expenses!$B:$B,$P$1,Expenses!$D:$D,B6,Expenses!$C:$C,$B$1) -> 0 | Q6: =SUMIFS(Expenses!$G:$G,Expenses!$B:$B,$Q$1,Expenses!$D:$D,B6,Expenses!$C:$C,$B$1) -> 0 | R6: =SUMIFS(Expenses!$G:$G,Expenses!$B:$B,$R$1,Expenses!$D:$D,B6,Expenses!$C:$C,$B$1) -> 0 | S6: =SUMIFS(Expenses!$G:$G,Expenses!$B:$B,$S$1,Expenses!$D:$D,B6,Expenses!$C:$C,$B$1) -> 0
A7: =SUM(C7:AA7) -> 150000 | B7: Rent | C7: =SUMIFS(Expenses!$G:$G,Expenses!$B:$B,$C$1,Expenses!$D:$D,B7,Expenses!$C:$C,$B$1) -> 0 | D7: =SUMIFS(Expenses!$G:$G,Expenses!$B:$B,$D$1,Expenses!$D:$D,B7,Expenses!$C:$C,$B$1) -> 0 | E7: =SUMIFS(Expenses!$G:$G,Expenses!$B:$B,$E$1,Expenses!$D:$D,B7,Expenses!$C:$C,$B$1) -> 0 | F7: =SUMIFS(Expenses!$G:$G,Expenses!$B:$B,$F$1,Expenses!$D:$D,B7,Expenses!$C:$C,$B$1) -> 0 | G7: =SUMIFS(Expenses!$G:$G,Expenses!$B:$B,$G$1,Expenses!$D:$D,B7,Expenses!$C:$C,$B$1) -> 0 | H7: =SUMIFS(Expenses!$G:$G,Expenses!$B:$B,$H$1,Expenses!$D:$D,B7,Expenses!$C:$C,$B$1) -> 0 | I7: =SUMIFS(Expenses!$G:$G,Expenses!$B:$B,$I$1,Expenses!$D:$D,B7,Expenses!$C:$C,$B$1) -> 0 | J7: =SUMIFS(Expenses!$G:$G,Expenses!$B:$B,$J$1,Expenses!$D:$D,B7,Expenses!$C:$C,$B$1) -> 0 | K7: =SUMIFS(Expenses!$G:$G,Expenses!$B:$B,$K$1,Expenses!$D:$D,B7,Expenses!$C:$C,$B$1) -> 0 | L7: =SUMIFS(Expenses!$G:$G,Expenses!$B:$B,$L$1,Expenses!$D:$D,B7,Expenses!$C:$C,$B$1) -> 50000 | M7: =SUMIFS(Expenses!$G:$G,Expenses!$B:$B,$M$1,Expenses!$D:$D,B7,Expenses!$C:$C,$B$1) -> 50000 | N7: =SUMIFS(Expenses!$G:$G,Expenses!$B:$B,$N$1,Expenses!$D:$D,B7,Expenses!$C:$C,$B$1) -> 50000 | O7: =SUMIFS(Expenses!$G:$G,Expenses!$B:$B,$O$1,Expenses!$D:$D,B7,Expenses!$C:$C,$B$1) -> 0 | P7: =SUMIFS(Expenses!$G:$G,Expenses!$B:$B,$P$1,Expenses!$D:$D,B7,Expenses!$C:$C,$B$1) -> 0 | Q7: =SUMIFS(Expenses!$G:$G,Expenses!$B:$B,$Q$1,Expenses!$D:$D,B7,Expenses!$C:$C,$B$1) -> 0 | R7: =SUMIFS(Expenses!$G:$G,Expenses!$B:$B,$R$1,Expenses!$D:$D,B7,Expenses!$C:$C,$B$1) -> 0 | S7: =SUMIFS(Expenses!$G:$G,Expenses!$B:$B,$S$1,Expenses!$D:$D,B7,Expenses!$C:$C,$B$1) -> 0
A8: =SUM(C8:AA8) -> 661300 | B8: Salary | C8: =SUMIFS(Expenses!$G:$G,Expenses!$B:$B,$C$1,Expenses!$D:$D,B8,Expenses!$C:$C,$B$1) -> 0 | D8: =SUMIFS(Expenses!$G:$G,Expenses!$B:$B,$D$1,Expenses!$D:$D,B8,Expenses!$C:$C,$B$1) -> 0 | E8: =SUMIFS(Expenses!$G:$G,Expenses!$B:$B,$E$1,Expenses!$D:$D,B8,Expenses!$C:$C,$B$1) -> 0 | F8: =SUMIFS(Expenses!$G:$G,Expenses!$B:$B,$F$1,Expenses!$D:$D,B8,Expenses!$C:$C,$B$1) -> 0 | G8: =SUMIFS(Expenses!$G:$G,Expenses!$B:$B,$G$1,Expenses!$D:$D,B8,Expenses!$C:$C,$B$1) -> 0 | H8: =SUMIFS(Expenses!$G:$G,Expenses!$B:$B,$H$1,Expenses!$D:$D,B8,Expenses!$C:$C,$B$1) -> 58500 | I8: =SUMIFS(Expenses!$G:$G,Expenses!$B:$B,$I$1,Expenses!$D:$D,B8,Expenses!$C:$C,$B$1) -> 65200 | J8: =SUMIFS(Expenses!$G:$G,Expenses!$B:$B,$J$1,Expenses!$D:$D,B8,Expenses!$C:$C,$B$1) -> 0 | K8: =SUMIFS(Expenses!$G:$G,Expenses!$B:$B,$K$1,Expenses!$D:$D,B8,Expenses!$C:$C,$B$1) -> 0 | L8: =SUMIFS(Expenses!$G:$G,Expenses!$B:$B,$L$1,Expenses!$D:$D,B8,Expenses!$C:$C,$B$1) -> 96000 | M8: =SUMIFS(Expenses!$G:$G,Expenses!$B:$B,$M$1,Expenses!$D:$D,B8,Expenses!$C:$C,$B$1) -> 143400 | N8: =SUMIFS(Expenses!$G:$G,Expenses!$B:$B,$N$1,Expenses!$D:$D,B8,Expenses!$C:$C,$B$1) -> 141200 | O8: =SUMIFS(Expenses!$G:$G,Expenses!$B:$B,$O$1,Expenses!$D:$D,B8,Expenses!$C:$C,$B$1) -> 157000 | P8: =SUMIFS(Expenses!$G:$G,Expenses!$B:$B,$P$1,Expenses!$D:$D,B8,Expenses!$C:$C,$B$1) -> 0 | Q8: =SUMIFS(Expenses!$G:$G,Expenses!$B:$B,$Q$1,Expenses!$D:$D,B8,Expenses!$C:$C,$B$1) -> 0 | R8: =SUMIFS(Expenses!$G:$G,Expenses!$B:$B,$R$1,Expenses!$D:$D,B8,Expenses!$C:$C,$B$1) -> 0 | S8: =SUMIFS(Expenses!$G:$G,Expenses!$B:$B,$S$1,Expenses!$D:$D,B8,Expenses!$C:$C,$B$1) -> 0
A9: =SUM(C9:AA9) -> 0 | B9: Protein Purchase | C9: =SUMIFS(Expenses!$G:$G,Expenses!$B:$B,$C$1,Expenses!$D:$D,B9,Expenses!$C:$C,$B$1) -> 0 | D9: =SUMIFS(Expenses!$G:$G,Expenses!$B:$B,$D$1,Expenses!$D:$D,B9,Expenses!$C:$C,$B$1) -> 0 | E9: =SUMIFS(Expenses!$G:$G,Expenses!$B:$B,$E$1,Expenses!$D:$D,B9,Expenses!$C:$C,$B$1) -> 0 | F9: =SUMIFS(Expenses!$G:$G,Expenses!$B:$B,$F$1,Expenses!$D:$D,B9,Expenses!$C:$C,$B$1) -> 0 | G9: =SUMIFS(Expenses!$G:$G,Expenses!$B:$B,$G$1,Expenses!$D:$D,B9,Expenses!$C:$C,$B$1) -> 0 | H9: =SUMIFS(Expenses!$G:$G,Expenses!$B:$B,$H$1,Expenses!$D:$D,B9,Expenses!$C:$C,$B$1) -> 0 | I9: =SUMIFS(Expenses!$G:$G,Expenses!$B:$B,$I$1,Expenses!$D:$D,B9,Expenses!$C:$C,$B$1) -> 0 | J9: =SUMIFS(Expenses!$G:$G,Expenses!$B:$B,$J$1,Expenses!$D:$D,B9,Expenses!$C:$C,$B$1) -> 0 | K9: =SUMIFS(Expenses!$G:$G,Expenses!$B:$B,$K$1,Expenses!$D:$D,B9,Expenses!$C:$C,$B$1) -> 0 | L9: =SUMIFS(Expenses!$G:$G,Expenses!$B:$B,$L$1,Expenses!$D:$D,B9,Expenses!$C:$C,$B$1) -> 0 | M9: =SUMIFS(Expenses!$G:$G,Expenses!$B:$B,$M$1,Expenses!$D:$D,B9,Expenses!$C:$C,$B$1) -> 0 | N9: =SUMIFS(Expenses!$G:$G,Expenses!$B:$B,$N$1,Expenses!$D:$D,B9,Expenses!$C:$C,$B$1) -> 0 | O9: =SUMIFS(Expenses!$G:$G,Expenses!$B:$B,$O$1,Expenses!$D:$D,B9,Expenses!$C:$C,$B$1) -> 0 | P9: =SUMIFS(Expenses!$G:$G,Expenses!$B:$B,$P$1,Expenses!$D:$D,B9,Expenses!$C:$C,$B$1) -> 0 | Q9: =SUMIFS(Expenses!$G:$G,Expenses!$B:$B,$Q$1,Expenses!$D:$D,B9,Expenses!$C:$C,$B$1) -> 0 | R9: =SUMIFS(Expenses!$G:$G,Expenses!$B:$B,$R$1,Expenses!$D:$D,B9,Expenses!$C:$C,$B$1) -> 0 | S9: =SUMIFS(Expenses!$G:$G,Expenses!$B:$B,$S$1,Expenses!$D:$D,B9,Expenses!$C:$C,$B$1) -> 0
A10: =SUM(C10:AA10) -> 0 | B10: Studio Share | C10: =SUMIFS(Expenses!$G:$G,Expenses!$B:$B,$C$1,Expenses!$D:$D,B10,Expenses!$C:$C,$B$1) -> 0 | D10: =SUMIFS(Expenses!$G:$G,Expenses!$B:$B,$D$1,Expenses!$D:$D,B10,Expenses!$C:$C,$B$1) -> 0 | E10: =SUMIFS(Expenses!$G:$G,Expenses!$B:$B,$E$1,Expenses!$D:$D,B10,Expenses!$C:$C,$B$1) -> 0 | F10: =SUMIFS(Expenses!$G:$G,Expenses!$B:$B,$F$1,Expenses!$D:$D,B10,Expenses!$C:$C,$B$1) -> 0 | G10: =SUMIFS(Expenses!$G:$G,Expenses!$B:$B,$G$1,Expenses!$D:$D,B10,Expenses!$C:$C,$B$1) -> 0 | H10: =SUMIFS(Expenses!$G:$G,Expenses!$B:$B,$H$1,Expenses!$D:$D,B10,Expenses!$C:$C,$B$1) -> 0 | I10: =SUMIFS(Expenses!$G:$G,Expenses!$B:$B,$I$1,Expenses!$D:$D,B10,Expenses!$C:$C,$B$1) -> 0 | J10: =SUMIFS(Expenses!$G:$G,Expenses!$B:$B,$J$1,Expenses!$D:$D,B10,Expenses!$C:$C,$B$1) -> 0 | K10: =SUMIFS(Expenses!$G:$G,Expenses!$B:$B,$K$1,Expenses!$D:$D,B10,Expenses!$C:$C,$B$1) -> 0 | L10: =SUMIFS(Expenses!$G:$G,Expenses!$B:$B,$L$1,Expenses!$D:$D,B10,Expenses!$C:$C,$B$1) -> 0 | M10: =SUMIFS(Expenses!$G:$G,Expenses!$B:$B,$M$1,Expenses!$D:$D,B10,Expenses!$C:$C,$B$1) -> 0 | N10: =SUMIFS(Expenses!$G:$G,Expenses!$B:$B,$N$1,Expenses!$D:$D,B10,Expenses!$C:$C,$B$1) -> 0 | O10: =SUMIFS(Expenses!$G:$G,Expenses!$B:$B,$O$1,Expenses!$D:$D,B10,Expenses!$C:$C,$B$1) -> 0 | P10: =SUMIFS(Expenses!$G:$G,Expenses!$B:$B,$P$1,Expenses!$D:$D,B10,Expenses!$C:$C,$B$1) -> 0 | Q10: =SUMIFS(Expenses!$G:$G,Expenses!$B:$B,$Q$1,Expenses!$D:$D,B10,Expenses!$C:$C,$B$1) -> 0 | R10: =SUMIFS(Expenses!$G:$G,Expenses!$B:$B,$R$1,Expenses!$D:$D,B10,Expenses!$C:$C,$B$1) -> 0 | S10: =SUMIFS(Expenses!$G:$G,Expenses!$B:$B,$S$1,Expenses!$D:$D,B10,Expenses!$C:$C,$B$1) -> 0
A11: =SUM(C11:AA11) -> 0 | B11: PT Share | C11: =SUMIFS(Expenses!$G:$G,Expenses!$B:$B,$C$1,Expenses!$D:$D,B11,Expenses!$C:$C,$B$1) -> 0 | D11: =SUMIFS(Expenses!$G:$G,Expenses!$B:$B,$D$1,Expenses!$D:$D,B11,Expenses!$C:$C,$B$1) -> 0 | E11: =SUMIFS(Expenses!$G:$G,Expenses!$B:$B,$E$1,Expenses!$D:$D,B11,Expenses!$C:$C,$B$1) -> 0 | F11: =SUMIFS(Expenses!$G:$G,Expenses!$B:$B,$F$1,Expenses!$D:$D,B11,Expenses!$C:$C,$B$1) -> 0 | G11: =SUMIFS(Expenses!$G:$G,Expenses!$B:$B,$G$1,Expenses!$D:$D,B11,Expenses!$C:$C,$B$1) -> 0 | H11: =SUMIFS(Expenses!$G:$G,Expenses!$B:$B,$H$1,Expenses!$D:$D,B11,Expenses!$C:$C,$B$1) -> 0 | I11: =SUMIFS(Expenses!$G:$G,Expenses!$B:$B,$I$1,Expenses!$D:$D,B11,Expenses!$C:$C,$B$1) -> 0 | J11: =SUMIFS(Expenses!$G:$G,Expenses!$B:$B,$J$1,Expenses!$D:$D,B11,Expenses!$C:$C,$B$1) -> 0 | K11: =SUMIFS(Expenses!$G:$G,Expenses!$B:$B,$K$1,Expenses!$D:$D,B11,Expenses!$C:$C,$B$1) -> 0 | L11: =SUMIFS(Expenses!$G:$G,Expenses!$B:$B,$L$1,Expenses!$D:$D,B11,Expenses!$C:$C,$B$1) -> 0 | M11: =SUMIFS(Expenses!$G:$G,Expenses!$B:$B,$M$1,Expenses!$D:$D,B11,Expenses!$C:$C,$B$1) -> 0 | N11: =SUMIFS(Expenses!$G:$G,Expenses!$B:$B,$N$1,Expenses!$D:$D,B11,Expenses!$C:$C,$B$1) -> 0 | O11: =SUMIFS(Expenses!$G:$G,Expenses!$B:$B,$O$1,Expenses!$D:$D,B11,Expenses!$C:$C,$B$1) -> 0 | P11: =SUMIFS(Expenses!$G:$G,Expenses!$B:$B,$P$1,Expenses!$D:$D,B11,Expenses!$C:$C,$B$1) -> 0 | Q11: =SUMIFS(Expenses!$G:$G,Expenses!$B:$B,$Q$1,Expenses!$D:$D,B11,Expenses!$C:$C,$B$1) -> 0 | R11: =SUMIFS(Expenses!$G:$G,Expenses!$B:$B,$R$1,Expenses!$D:$D,B11,Expenses!$C:$C,$B$1) -> 0 | S11: =SUMIFS(Expenses!$G:$G,Expenses!$B:$B,$S$1,Expenses!$D:$D,B11,Expenses!$C:$C,$B$1) -> 0
A12: =SUM(C12:AA12) -> 8640 | B12: Misc | C12: =SUMIFS(Expenses!$G:$G,Expenses!$B:$B,$C$1,Expenses!$D:$D,B12,Expenses!$C:$C,$B$1) -> 0 | D12: =SUMIFS(Expenses!$G:$G,Expenses!$B:$B,$D$1,Expenses!$D:$D,B12,Expenses!$C:$C,$B$1) -> 0 | E12: =SUMIFS(Expenses!$G:$G,Expenses!$B:$B,$E$1,Expenses!$D:$D,B12,Expenses!$C:$C,$B$1) -> 0 | F12: =SUMIFS(Expenses!$G:$G,Expenses!$B:$B,$F$1,Expenses!$D:$D,B12,Expenses!$C:$C,$B$1) -> 0 | G12: =SUMIFS(Expenses!$G:$G,Expenses!$B:$B,$G$1,Expenses!$D:$D,B12,Expenses!$C:$C,$B$1) -> 0 | H12: =SUMIFS(Expenses!$G:$G,Expenses!$B:$B,$H$1,Expenses!$D:$D,B12,Expenses!$C:$C,$B$1) -> 0 | I12: =SUMIFS(Expenses!$G:$G,Expenses!$B:$B,$I$1,Expenses!$D:$D,B12,Expenses!$C:$C,$B$1) -> 0 | J12: =SUMIFS(Expenses!$G:$G,Expenses!$B:$B,$J$1,Expenses!$D:$D,B12,Expenses!$C:$C,$B$1) -> 0 | K12: =SUMIFS(Expenses!$G:$G,Expenses!$B:$B,$K$1,Expenses!$D:$D,B12,Expenses!$C:$C,$B$1) -> 0 | L12: =SUMIFS(Expenses!$G:$G,Expenses!$B:$B,$L$1,Expenses!$D:$D,B12,Expenses!$C:$C,$B$1) -> 1483 | M12: =SUMIFS(Expenses!$G:$G,Expenses!$B:$B,$M$1,Expenses!$D:$D,B12,Expenses!$C:$C,$B$1) -> 5609 | N12: =SUMIFS(Expenses!$G:$G,Expenses!$B:$B,$N$1,Expenses!$D:$D,B12,Expenses!$C:$C,$B$1) -> 1548 | O12: =SUMIFS(Expenses!$G:$G,Expenses!$B:$B,$O$1,Expenses!$D:$D,B12,Expenses!$C:$C,$B$1) -> 0 | P12: =SUMIFS(Expenses!$G:$G,Expenses!$B:$B,$P$1,Expenses!$D:$D,B12,Expenses!$C:$C,$B$1) -> 0 | Q12: =SUMIFS(Expenses!$G:$G,Expenses!$B:$B,$Q$1,Expenses!$D:$D,B12,Expenses!$C:$C,$B$1) -> 0 | R12: =SUMIFS(Expenses!$G:$G,Expenses!$B:$B,$R$1,Expenses!$D:$D,B12,Expenses!$C:$C,$B$1) -> 0 | S12: =SUMIFS(Expenses!$G:$G,Expenses!$B:$B,$S$1,Expenses!$D:$D,B12,Expenses!$C:$C,$B$1) -> 0
A13: =SUM(C13:AA13) -> 0 | B13: Wasif Share | C13: =SUMIFS(Expenses!$G:$G,Expenses!$B:$B,$C$1,Expenses!$D:$D,B13,Expenses!$C:$C,$B$1) -> 0 | D13: =SUMIFS(Expenses!$G:$G,Expenses!$B:$B,$D$1,Expenses!$D:$D,B13,Expenses!$C:$C,$B$1) -> 0 | E13: =SUMIFS(Expenses!$G:$G,Expenses!$B:$B,$E$1,Expenses!$D:$D,B13,Expenses!$C:$C,$B$1) -> 0 | F13: =SUMIFS(Expenses!$G:$G,Expenses!$B:$B,$F$1,Expenses!$D:$D,B13,Expenses!$C:$C,$B$1) -> 0 | G13: =SUMIFS(Expenses!$G:$G,Expenses!$B:$B,$G$1,Expenses!$D:$D,B13,Expenses!$C:$C,$B$1) -> 0 | H13: =SUMIFS(Expenses!$G:$G,Expenses!$B:$B,$H$1,Expenses!$D:$D,B13,Expenses!$C:$C,$B$1) -> 0 | I13: =SUMIFS(Expenses!$G:$G,Expenses!$B:$B,$I$1,Expenses!$D:$D,B13,Expenses!$C:$C,$B$1) -> 0 | J13: =SUMIFS(Expenses!$G:$G,Expenses!$B:$B,$J$1,Expenses!$D:$D,B13,Expenses!$C:$C,$B$1) -> 0 | K13: =SUMIFS(Expenses!$G:$G,Expenses!$B:$B,$K$1,Expenses!$D:$D,B13,Expenses!$C:$C,$B$1) -> 0 | L13: =SUMIFS(Expenses!$G:$G,Expenses!$B:$B,$L$1,Expenses!$D:$D,B13,Expenses!$C:$C,$B$1) -> 0 | M13: =SUMIFS(Expenses!$G:$G,Expenses!$B:$B,$M$1,Expenses!$D:$D,B13,Expenses!$C:$C,$B$1) -> 0 | N13: =SUMIFS(Expenses!$G:$G,Expenses!$B:$B,$N$1,Expenses!$D:$D,B13,Expenses!$C:$C,$B$1) -> 0 | O13: =SUMIFS(Expenses!$G:$G,Expenses!$B:$B,$O$1,Expenses!$D:$D,B13,Expenses!$C:$C,$B$1) -> 0 | P13: =SUMIFS(Expenses!$G:$G,Expenses!$B:$B,$P$1,Expenses!$D:$D,B13,Expenses!$C:$C,$B$1) -> 0 | Q13: =SUMIFS(Expenses!$G:$G,Expenses!$B:$B,$Q$1,Expenses!$D:$D,B13,Expenses!$C:$C,$B$1) -> 0 | R13: =SUMIFS(Expenses!$G:$G,Expenses!$B:$B,$R$1,Expenses!$D:$D,B13,Expenses!$C:$C,$B$1) -> 0 | S13: =SUMIFS(Expenses!$G:$G,Expenses!$B:$B,$S$1,Expenses!$D:$D,B13,Expenses!$C:$C,$B$1) -> 0
A14: =SUM(C14:AA14) -> 0 | B14: Diesel | C14: =SUMIFS(Expenses!$G:$G,Expenses!$B:$B,$C$1,Expenses!$D:$D,B14,Expenses!$C:$C,$B$1) -> 0 | D14: =SUMIFS(Expenses!$G:$G,Expenses!$B:$B,$D$1,Expenses!$D:$D,B14,Expenses!$C:$C,$B$1) -> 0 | E14: =SUMIFS(Expenses!$G:$G,Expenses!$B:$B,$E$1,Expenses!$D:$D,B14,Expenses!$C:$C,$B$1) -> 0 | F14: =SUMIFS(Expenses!$G:$G,Expenses!$B:$B,$F$1,Expenses!$D:$D,B14,Expenses!$C:$C,$B$1) -> 0 | G14: =SUMIFS(Expenses!$G:$G,Expenses!$B:$B,$G$1,Expenses!$D:$D,B14,Expenses!$C:$C,$B$1) -> 0 | H14: =SUMIFS(Expenses!$G:$G,Expenses!$B:$B,$H$1,Expenses!$D:$D,B14,Expenses!$C:$C,$B$1) -> 0 | I14: =SUMIFS(Expenses!$G:$G,Expenses!$B:$B,$I$1,Expenses!$D:$D,B14,Expenses!$C:$C,$B$1) -> 0 | J14: =SUMIFS(Expenses!$G:$G,Expenses!$B:$B,$J$1,Expenses!$D:$D,B14,Expenses!$C:$C,$B$1) -> 0 | K14: =SUMIFS(Expenses!$G:$G,Expenses!$B:$B,$K$1,Expenses!$D:$D,B14,Expenses!$C:$C,$B$1) -> 0 | L14: =SUMIFS(Expenses!$G:$G,Expenses!$B:$B,$L$1,Expenses!$D:$D,B14,Expenses!$C:$C,$B$1) -> 0 | M14: =SUMIFS(Expenses!$G:$G,Expenses!$B:$B,$M$1,Expenses!$D:$D,B14,Expenses!$C:$C,$B$1) -> 0 | N14: =SUMIFS(Expenses!$G:$G,Expenses!$B:$B,$N$1,Expenses!$D:$D,B14,Expenses!$C:$C,$B$1) -> 0 | O14: =SUMIFS(Expenses!$G:$G,Expenses!$B:$B,$O$1,Expenses!$D:$D,B14,Expenses!$C:$C,$B$1) -> 0 | P14: =SUMIFS(Expenses!$G:$G,Expenses!$B:$B,$P$1,Expenses!$D:$D,B14,Expenses!$C:$C,$B$1) -> 0 | Q14: =SUMIFS(Expenses!$G:$G,Expenses!$B:$B,$Q$1,Expenses!$D:$D,B14,Expenses!$C:$C,$B$1) -> 0 | R14: =SUMIFS(Expenses!$G:$G,Expenses!$B:$B,$R$1,Expenses!$D:$D,B14,Expenses!$C:$C,$B$1) -> 0 | S14: =SUMIFS(Expenses!$G:$G,Expenses!$B:$B,$S$1,Expenses!$D:$D,B14,Expenses!$C:$C,$B$1) -> 0
... A17: =SUM(C17:AA17) -> 962000 | B17: Kitchen Equipments | C17: =SUMIFS(Expenses!$G:$G,Expenses!$B:$B,$C$1,Expenses!$D:$D,B17,Expenses!$C:$C,$B$1) -> 200000 | D17: =SUMIFS(Expenses!$G:$G,Expenses!$B:$B,$D$1,Expenses!$D:$D,B17,Expenses!$C:$C,$B$1) -> 300000 | E17: =SUMIFS(Expenses!$G:$G,Expenses!$B:$B,$E$1,Expenses!$D:$D,B17,Expenses!$C:$C,$B$1) -> 257000 | F17: =SUMIFS(Expenses!$G:$G,Expenses!$B:$B,$F$1,Expenses!$D:$D,B17,Expenses!$C:$C,$B$1) -> 205000 | G17: =SUMIFS(Expenses!$G:$G,Expenses!$B:$B,$G$1,Expenses!$D:$D,B17,Expenses!$C:$C,$B$1) -> 0 | H17: =SUMIFS(Expenses!$G:$G,Expenses!$B:$B,$H$1,Expenses!$D:$D,B17,Expenses!$C:$C,$B$1) -> 0 | I17: =SUMIFS(Expenses!$G:$G,Expenses!$B:$B,$I$1,Expenses!$D:$D,B17,Expenses!$C:$C,$B$1) -> 0 | J17: =SUMIFS(Expenses!$G:$G,Expenses!$B:$B,$J$1,Expenses!$D:$D,B17,Expenses!$C:$C,$B$1) -> 0 | K17: =SUMIFS(Expenses!$G:$G,Expenses!$B:$B,$K$1,Expenses!$D:$D,B17,Expenses!$C:$C,$B$1) -> 0 | L17: =SUMIFS(Expenses!$G:$G,Expenses!$B:$B,$L$1,Expenses!$D:$D,B17,Expenses!$C:$C,$B$1) -> 0 | M17: =SUMIFS(Expenses!$G:$G,Expenses!$B:$B,$M$1,Expenses!$D:$D,B17,Expenses!$C:$C,$B$1) -> 0 | N17: =SUMIFS(Expenses!$G:$G,Expenses!$B:$B,$N$1,Expenses!$D:$D,B17,Expenses!$C:$C,$B$1) -> 0 | O17: =SUMIFS(Expenses!$G:$G,Expenses!$B:$B,$O$1,Expenses!$D:$D,B17,Expenses!$C:$C,$B$1) -> 0 | P17: =SUMIFS(Expenses!$G:$G,Expenses!$B:$B,$P$1,Expenses!$D:$D,B17,Expenses!$C:$C,$B$1) -> 0 | Q17: =SUMIFS(Expenses!$G:$G,Expenses!$B:$B,$Q$1,Expenses!$D:$D,B17,Expenses!$C:$C,$B$1) -> 0 | R17: =SUMIFS(Expenses!$G:$G,Expenses!$B:$B,$R$1,Expenses!$D:$D,B17,Expenses!$C:$C,$B$1) -> 0 | S17: =SUMIFS(Expenses!$G:$G,Expenses!$B:$B,$S$1,Expenses!$D:$D,B17,Expenses!$C:$C,$B$1) -> 0
A18: =SUM(C18:AA18) -> 162578 | B18: XCAL Food Purchase | C18: =SUMIFS(Expenses!$G:$G,Expenses!$B:$B,$C$1,Expenses!$D:$D,B18,Expenses!$C:$C,$B$1) -> 0 | D18: =SUMIFS(Expenses!$G:$G,Expenses!$B:$B,$D$1,Expenses!$D:$D,B18,Expenses!$C:$C,$B$1) -> 0 | E18: =SUMIFS(Expenses!$G:$G,Expenses!$B:$B,$E$1,Expenses!$D:$D,B18,Expenses!$C:$C,$B$1) -> 0 | F18: =SUMIFS(Expenses!$G:$G,Expenses!$B:$B,$F$1,Expenses!$D:$D,B18,Expenses!$C:$C,$B$1) -> 0 | G18: =SUMIFS(Expenses!$G:$G,Expenses!$B:$B,$G$1,Expenses!$D:$D,B18,Expenses!$C:$C,$B$1) -> 0 | H18: =SUMIFS(Expenses!$G:$G,Expenses!$B:$B,$H$1,Expenses!$D:$D,B18,Expenses!$C:$C,$B$1) -> 61541 | I18: =SUMIFS(Expenses!$G:$G,Expenses!$B:$B,$I$1,Expenses!$D:$D,B18,Expenses!$C:$C,$B$1) -> 101037 | J18: =SUMIFS(Expenses!$G:$G,Expenses!$B:$B,$J$1,Expenses!$D:$D,B18,Expenses!$C:$C,$B$1) -> 0 | K18: =SUMIFS(Expenses!$G:$G,Expenses!$B:$B,$K$1,Expenses!$D:$D,B18,Expenses!$C:$C,$B$1) -> 0 | L18: =SUMIFS(Expenses!$G:$G,Expenses!$B:$B,$L$1,Expenses!$D:$D,B18,Expenses!$C:$C,$B$1) -> 0 | M18: =SUMIFS(Expenses!$G:$G,Expenses!$B:$B,$M$1,Expenses!$D:$D,B18,Expenses!$C:$C,$B$1) -> 0 | N18: =SUMIFS(Expenses!$G:$G,Expenses!$B:$B,$N$1,Expenses!$D:$D,B18,Expenses!$C:$C,$B$1) -> 0 | O18: =SUMIFS(Expenses!$G:$G,Expenses!$B:$B,$O$1,Expenses!$D:$D,$B$2,Expenses!$C:$C,$B$1) -> 0 | P18: =SUMIFS(Expenses!$G:$G,Expenses!$B:$B,$P$1,Expenses!$D:$D,B18,Expenses!$C:$C,$B$1) -> 0 | Q18: =SUMIFS(Expenses!$G:$G,Expenses!$B:$B,$Q$1,Expenses!$D:$D,B18,Expenses!$C:$C,$B$1) -> 0 | R18: =SUMIFS(Expenses!$G:$G,Expenses!$B:$B,$R$1,Expenses!$D:$D,B18,Expenses!$C:$C,$B$1) -> 0 | S18: =SUMIFS(Expenses!$G:$G,Expenses!$B:$B,$S$1,Expenses!$D:$D,B18,Expenses!$C:$C,$B$1) -> 0
A19: =SUM(A2:A18) -> 3240250 | B19: TOTAL | C19: =SUM(C2:C18) -> 200000 | D19: =SUM(D2:D18) -> 350000 | E19: =SUM(E2:E18) -> 551054 | F19: =SUM(F2:F18) -> 300900 | G19: =SUM(G2:G18) -> 65000 | H19: =SUM(H2:H18) -> 266809 | I19: =SUM(I2:I18) -> 166237 | J19: =SUM(J2:J18) -> 0 | ... S19: =SUM(S2:S18) -> 0
A21: Total | B21: Official | C21: =C1 -> 43678 | D21: =D1 -> 43709 | E21: =E1 -> 43739 | F21: =F1 -> 43770 | G21: =G1 -> 43800 | H21: =H1 -> 43831 | I21: =I1 -> 43862 | J21: =J1 -> 43891 | ... S21: =S1 -> 44166
A22: =SUM(C22:AA22) -> 0 | B22: Utility | C22: =SUMIFS(Expenses!$G:$G,Expenses!$B:$B,$C$1,Expenses!$D:$D,B22,Expenses!$C:$C,$B$21) -> 0 | D22: =SUMIFS(Expenses!$G:$G,Expenses!$B:$B,$D$1,Expenses!$D:$D,B22,Expenses!$C:$C,$B$21) -> 0 | E22: =SUMIFS(Expenses!$G:$G,Expenses!$B:$B,$E$1,Expenses!$D:$D,B22,Expenses!$C:$C,$B$21) -> 0 | F22: =SUMIFS(Expenses!$G:$G,Expenses!$B:$B,$F$1,Expenses!$D:$D,B22,Expenses!$C:$C,$B$21) -> 0 | G22: =SUMIFS(Expenses!$G:$G,Expenses!$B:$B,$G$1,Expenses!$D:$D,B22,Expenses!$C:$C,$B$21) -> 0 | H22: =SUMIFS(Expenses!$G:$G,Expenses!$B:$B,$H$1,Expenses!$D:$D,B22,Expenses!$C:$C,$B$21) -> 0 | I22: =SUMIFS(Expenses!$G:$G,Expenses!$B:$B,$I$1,Expenses!$D:$D,B22,Expenses!$C:$C,$B$21) -> 0 | J22: =SUMIFS(Expenses!$G:$G,Expenses!$B:$B,$J$1,Expenses!$D:$D,B22,Expenses!$C:$C,$B$21) -> 0 | K22: =SUMIFS(Expenses!$G:$G,Expenses!$B:$B,$K$1,Expenses!$D:$D,B22,Expenses!$C:$C,$B$21) -> 0 | L22: =SUMIFS(Expenses!$G:$G,Expenses!$B:$B,$L$1,Expenses!$D:$D,B22,Expenses!$C:$C,$B$21) -> 0 | M22: =SUMIFS(Expenses!$G:$G,Expenses!$B:$B,$M$1,Expenses!$D:$D,B22,Expenses!$C:$C,$B$21) -> 0 | N22: =SUMIFS(Expenses!$G:$G,Expenses!$B:$B,$N$1,Expenses!$D:$D,B22,Expenses!$C:$C,$B$21) -> 0 | O22: =SUMIFS(Expenses!$G:$G,Expenses!$B:$B,$O$1,Expenses!$D:$D,B22,Expenses!$C:$C,$B$21) -> 0 | P22: =SUMIFS(Expenses!$G:$G,Expenses!$B:$B,$P$1,Expenses!$D:$D,B22,Expenses!$C:$C,$B$21) -> 0 | Q22: =SUMIFS(Expenses!$G:$G,Expenses!$B:$B,$Q$1,Expenses!$D:$D,B22,Expenses!$C:$C,$B$21) -> 0 | R22: =SUMIFS(Expenses!$G:$G,Expenses!$B:$B,$R$1,Expenses!$D:$D,B22,Expenses!$C:$C,$B$21) -> 0 | S22: =SUMIFS(Expenses!$G:$G,Expenses!$B:$B,$S$1,Expenses!$D:$D,B22,Expenses!$C:$C,$B$21) -> 0
A23: =SUM(C23:AA23) -> 0 | B23: Accessories | C23: =SUMIFS(Expenses!$G:$G,Expenses!$B:$B,$C$1,Expenses!$D:$D,B23,Expenses!$C:$C,$B$21) -> 0 | D23: =SUMIFS(Expenses!$G:$G,Expenses!$B:$B,$D$1,Expenses!$D:$D,B23,Expenses!$C:$C,$B$21) -> 0 | E23: =SUMIFS(Expenses!$G:$G,Expenses!$B:$B,$E$1,Expenses!$D:$D,B23,Expenses!$C:$C,$B$21) -> 0 | F23: =SUMIFS(Expenses!$G:$G,Expenses!$B:$B,$F$1,Expenses!$D:$D,B23,Expenses!$C:$C,$B$21) -> 0 | G23: =SUMIFS(Expenses!$G:$G,Expenses!$B:$B,$G$1,Expenses!$D:$D,B23,Expenses!$C:$C,$B$21) -> 0 | H23: =SUMIFS(Expenses!$G:$G,Expenses!$B:$B,$H$1,Expenses!$D:$D,B23,Expenses!$C:$C,$B$21) -> 0 | I23: =SUMIFS(Expenses!$G:$G,Expenses!$B:$B,$I$1,Expenses!$D:$D,B23,Expenses!$C:$C,$B$21) -> 0 | J23: =SUMIFS(Expenses!$G:$G,Expenses!$B:$B,$J$1,Expenses!$D:$D,B23,Expenses!$C:$C,$B$21) -> 0 | K23: =SUMIFS(Expenses!$G:$G,Expenses!$B:$B,$K$1,Expenses!$D:$D,B23,Expenses!$C:$C,$B$21) -> 0 | L23: =SUMIFS(Expenses!$G:$G,Expenses!$B:$B,$L$1,Expenses!$D:$D,B23,Expenses!$C:$C,$B$21) -> 0 | M23: =SUMIFS(Expenses!$G:$G,Expenses!$B:$B,$M$1,Expenses!$D:$D,B23,Expenses!$C:$C,$B$21) -> 0 | N23: =SUMIFS(Expenses!$G:$G,Expenses!$B:$B,$N$1,Expenses!$D:$D,B23,Expenses!$C:$C,$B$21) -> 0 | O23: =SUMIFS(Expenses!$G:$G,Expenses!$B:$B,$O$1,Expenses!$D:$D,B23,Expenses!$C:$C,$B$21) -> 0 | P23: =SUMIFS(Expenses!$G:$G,Expenses!$B:$B,$P$1,Expenses!$D:$D,B23,Expenses!$C:$C,$B$21) -> 0 | Q23: =SUMIFS(Expenses!$G:$G,Expenses!$B:$B,$Q$1,Expenses!$D:$D,B23,Expenses!$C:$C,$B$21) -> 0 | R23: =SUMIFS(Expenses!$G:$G,Expenses!$B:$B,$R$1,Expenses!$D:$D,B23,Expenses!$C:$C,$B$21) -> 0 | S23: =SUMIFS(Expenses!$G:$G,Expenses!$B:$B,$S$1,Expenses!$D:$D,B23,Expenses!$C:$C,$B$21) -> 0
A24: =SUM(C24:AA24) -> 0 | B24: Marketing | C24: =SUMIFS(Expenses!$G:$G,Expenses!$B:$B,$C$1,Expenses!$D:$D,B24,Expenses!$C:$C,$B$21) -> 0 | D24: =SUMIFS(Expenses!$G:$G,Expenses!$B:$B,$D$1,Expenses!$D:$D,B24,Expenses!$C:$C,$B$21) -> 0 | E24: =SUMIFS(Expenses!$G:$G,Expenses!$B:$B,$E$1,Expenses!$D:$D,B24,Expenses!$C:$C,$B$21) -> 0 | F24: =SUMIFS(Expenses!$G:$G,Expenses!$B:$B,$F$1,Expenses!$D:$D,B24,Expenses!$C:$C,$B$21) -> 0 | G24: =SUMIFS(Expenses!$G:$G,Expenses!$B:$B,$G$1,Expenses!$D:$D,B24,Expenses!$C:$C,$B$21) -> 0 | H24: =SUMIFS(Expenses!$G:$G,Expenses!$B:$B,$H$1,Expenses!$D:$D,B24,Expenses!$C:$C,$B$21) -> 0 | I24: =SUMIFS(Expenses!$G:$G,Expenses!$B:$B,$I$1,Expenses!$D:$D,B24,Expenses!$C:$C,$B$21) -> 0 | J24: =SUMIFS(Expenses!$G:$G,Expenses!$B:$B,$J$1,Expenses!$D:$D,B24,Expenses!$C:$C,$B$21) -> 0 | K24: =SUMIFS(Expenses!$G:$G,Expenses!$B:$B,$K$1,Expenses!$D:$D,B24,Expenses!$C:$C,$B$21) -> 0 | L24: =SUMIFS(Expenses!$G:$G,Expenses!$B:$B,$L$1,Expenses!$D:$D,B24,Expenses!$C:$C,$B$21) -> 0 | M24: =SUMIFS(Expenses!$G:$G,Expenses!$B:$B,$M$1,Expenses!$D:$D,B24,Expenses!$C:$C,$B$21) -> 0 | N24: =SUMIFS(Expenses!$G:$G,Expenses!$B:$B,$N$1,Expenses!$D:$D,B24,Expenses!$C:$C,$B$21) -> 0 | O24: =SUMIFS(Expenses!$G:$G,Expenses!$B:$B,$O$1,Expenses!$D:$D,B24,Expenses!$C:$C,$B$21) -> 0 | P24: =SUMIFS(Expenses!$G:$G,Expenses!$B:$B,$P$1,Expenses!$D:$D,B24,Expenses!$C:$C,$B$21) -> 0 | Q24: =SUMIFS(Expenses!$G:$G,Expenses!$B:$B,$Q$1,Expenses!$D:$D,B24,Expenses!$C:$C,$B$21) -> 0 | R24: =SUMIFS(Expenses!$G:$G,Expenses!$B:$B,$R$1,Expenses!$D:$D,B24,Expenses!$C:$C,$B$21) -> 0 | S24: =SUMIFS(Expenses!$G:$G,Expenses!$B:$B,$S$1,Expenses!$D:$D,B24,Expenses!$C:$C,$B$21) -> 0
A25: =SUM(C25:AA25) -> 0 | B25: Petty Cash | C25: =SUMIFS(Expenses!$G:$G,Expenses!$B:$B,$C$1,Expenses!$D:$D,B25,Expenses!$C:$C,$B$21) -> 0 | D25: =SUMIFS(Expenses!$G:$G,Expenses!$B:$B,$D$1,Expenses!$D:$D,B25,Expenses!$C:$C,$B$21) -> 0 | E25: =SUMIFS(Expenses!$G:$G,Expenses!$B:$B,$E$1,Expenses!$D:$D,B25,Expenses!$C:$C,$B$21) -> 0 | F25: =SUMIFS(Expenses!$G:$G,Expenses!$B:$B,$F$1,Expenses!$D:$D,B25,Expenses!$C:$C,$B$21) -> 0 | G25: =SUMIFS(Expenses!$G:$G,Expenses!$B:$B,$G$1,Expenses!$D:$D,B25,Expenses!$C:$C,$B$21) -> 0 | H25: =SUMIFS(Expenses!$G:$G,Expenses!$B:$B,$H$1,Expenses!$D:$D,B25,Expenses!$C:$C,$B$21) -> 0 | I25: =SUMIFS(Expenses!$G:$G,Expenses!$B:$B,$I$1,Expenses!$D:$D,B25,Expenses!$C:$C,$B$21) -> 0 | J25: =SUMIFS(Expenses!$G:$G,Expenses!$B:$B,$J$1,Expenses!$D:$D,B25,Expenses!$C:$C,$B$21) -> 0 | K25: =SUMIFS(Expenses!$G:$G,Expenses!$B:$B,$K$1,Expenses!$D:$D,B25,Expenses!$C:$C,$B$21) -> 0 | L25: =SUMIFS(Expenses!$G:$G,Expenses!$B:$B,$L$1,Expenses!$D:$D,B25,Expenses!$C:$C,$B$21) -> 0 | M25: =SUMIFS(Expenses!$G:$G,Expenses!$B:$B,$M$1,Expenses!$D:$D,B25,Expenses!$C:$C,$B$21) -> 0 | N25: =SUMIFS(Expenses!$G:$G,Expenses!$B:$B,$N$1,Expenses!$D:$D,B25,Expenses!$C:$C,$B$21) -> 0 | O25: =SUMIFS(Expenses!$G:$G,Expenses!$B:$B,$O$1,Expenses!$D:$D,B25,Expenses!$C:$C,$B$21) -> 0 | P25: =SUMIFS(Expenses!$G:$G,Expenses!$B:$B,$P$1,Expenses!$D:$D,B25,Expenses!$C:$C,$B$21) -> 0 | Q25: =SUMIFS(Expenses!$G:$G,Expenses!$B:$B,$Q$1,Expenses!$D:$D,B25,Expenses!$C:$C,$B$21) -> 0 | R25: =SUMIFS(Expenses!$G:$G,Expenses!$B:$B,$R$1,Expenses!$D:$D,B25,Expenses!$C:$C,$B$21) -> 0 | S25: =SUMIFS(Expenses!$G:$G,Expenses!$B:$B,$S$1,Expenses!$D:$D,B25,Expenses!$C:$C,$B$21) -> 0
A26: =SUM(C26:AA26) -> 0 | B26: Construction | C26: =SUMIFS(Expenses!$G:$G,Expenses!$B:$B,$C$1,Expenses!$D:$D,B26,Expenses!$C:$C,$B$21) -> 0 | D26: =SUMIFS(Expenses!$G:$G,Expenses!$B:$B,$D$1,Expenses!$D:$D,B26,Expenses!$C:$C,$B$21) -> 0 | E26: =SUMIFS(Expenses!$G:$G,Expenses!$B:$B,$E$1,Expenses!$D:$D,B26,Expenses!$C:$C,$B$21) -> 0 | F26: =SUMIFS(Expenses!$G:$G,Expenses!$B:$B,$F$1,Expenses!$D:$D,B26,Expenses!$C:$C,$B$21) -> 0 | G26: =SUMIFS(Expenses!$G:$G,Expenses!$B:$B,$G$1,Expenses!$D:$D,B26,Expenses!$C:$C,$B$21) -> 0 | H26: =SUMIFS(Expenses!$G:$G,Expenses!$B:$B,$H$1,Expenses!$D:$D,B26,Expenses!$C:$C,$B$21) -> 0 | I26: =SUMIFS(Expenses!$G:$G,Expenses!$B:$B,$I$1,Expenses!$D:$D,B26,Expenses!$C:$C,$B$21) -> 0 | J26: =SUMIFS(Expenses!$G:$G,Expenses!$B:$B,$J$1,Expenses!$D:$D,B26,Expenses!$C:$C,$B$21) -> 0 | K26: =SUMIFS(Expenses!$G:$G,Expenses!$B:$B,$K$1,Expenses!$D:$D,B26,Expenses!$C:$C,$B$21) -> 0 | L26: =SUMIFS(Expenses!$G:$G,Expenses!$B:$B,$L$1,Expenses!$D:$D,B26,Expenses!$C:$C,$B$21) -> 0 | M26: =SUMIFS(Expenses!$G:$G,Expenses!$B:$B,$M$1,Expenses!$D:$D,B26,Expenses!$C:$C,$B$21) -> 0 | N26: =SUMIFS(Expenses!$G:$G,Expenses!$B:$B,$N$1,Expenses!$D:$D,B26,Expenses!$C:$C,$B$21) -> 0 | O26: =SUMIFS(Expenses!$G:$G,Expenses!$B:$B,$O$1,Expenses!$D:$D,B26,Expenses!$C:$C,$B$21) -> 0 | P26: =SUMIFS(Expenses!$G:$G,Expenses!$B:$B,$P$1,Expenses!$D:$D,B26,Expenses!$C:$C,$B$21) -> 0 | Q26: =SUMIFS(Expenses!$G:$G,Expenses!$B:$B,$Q$1,Expenses!$D:$D,B26,Expenses!$C:$C,$B$21) -> 0 | R26: =SUMIFS(Expenses!$G:$G,Expenses!$B:$B,$R$1,Expenses!$D:$D,B26,Expenses!$C:$C,$B$21) -> 0 | S26: =SUMIFS(Expenses!$G:$G,Expenses!$B:$B,$S$1,Expenses!$D:$D,B26,Expenses!$C:$C,$B$21) -> 0
A27: =SUM(C27:AA27) -> 0 | B27: Rent | C27: =SUMIFS(Expenses!$G:$G,Expenses!$B:$B,$C$1,Expenses!$D:$D,B27,Expenses!$C:$C,$B$21) -> 0 | D27: =SUMIFS(Expenses!$G:$G,Expenses!$B:$B,$D$1,Expenses!$D:$D,B27,Expenses!$C:$C,$B$21) -> 0 | E27: =SUMIFS(Expenses!$G:$G,Expenses!$B:$B,$E$1,Expenses!$D:$D,B27,Expenses!$C:$C,$B$21) -> 0 | F27: =SUMIFS(Expenses!$G:$G,Expenses!$B:$B,$F$1,Expenses!$D:$D,B27,Expenses!$C:$C,$B$21) -> 0 | G27: =SUMIFS(Expenses!$G:$G,Expenses!$B:$B,$G$1,Expenses!$D:$D,B27,Expenses!$C:$C,$B$21) -> 0 | H27: =SUMIFS(Expenses!$G:$G,Expenses!$B:$B,$H$1,Expenses!$D:$D,B27,Expenses!$C:$C,$B$21) -> 0 | I27: =SUMIFS(Expenses!$G:$G,Expenses!$B:$B,$I$1,Expenses!$D:$D,B27,Expenses!$C:$C,$B$21) -> 0 | J27: =SUMIFS(Expenses!$G:$G,Expenses!$B:$B,$J$1,Expenses!$D:$D,B27,Expenses!$C:$C,$B$21) -> 0 | K27: =SUMIFS(Expenses!$G:$G,Expenses!$B:$B,$K$1,Expenses!$D:$D,B27,Expenses!$C:$C,$B$21) -> 0 | L27: =SUMIFS(Expenses!$G:$G,Expenses!$B:$B,$L$1,Expenses!$D:$D,B27,Expenses!$C:$C,$B$21) -> 0 | M27: =SUMIFS(Expenses!$G:$G,Expenses!$B:$B,$M$1,Expenses!$D:$D,B27,Expenses!$C:$C,$B$21) -> 0 | N27: =SUMIFS(Expenses!$G:$G,Expenses!$B:$B,$N$1,Expenses!$D:$D,B27,Expenses!$C:$C,$B$21) -> 0 | O27: =SUMIFS(Expenses!$G:$G,Expenses!$B:$B,$O$1,Expenses!$D:$D,B27,Expenses!$C:$C,$B$21) -> 0 | P27: =SUMIFS(Expenses!$G:$G,Expenses!$B:$B,$P$1,Expenses!$D:$D,B27,Expenses!$C:$C,$B$21) -> 0 | Q27: =SUMIFS(Expenses!$G:$G,Expenses!$B:$B,$Q$1,Expenses!$D:$D,B27,Expenses!$C:$C,$B$21) -> 0 | R27: =SUMIFS(Expenses!$G:$G,Expenses!$B:$B,$R$1,Expenses!$D:$D,B27,Expenses!$C:$C,$B$21) -> 0 | S27: =SUMIFS(Expenses!$G:$G,Expenses!$B:$B,$S$1,Expenses!$D:$D,B27,Expenses!$C:$C,$B$21) -> 0
A28: =SUM(C28:AA28) -> 0 | B28: Salary | C28: =SUMIFS(Expenses!$G:$G,Expenses!$B:$B,$C$1,Expenses!$D:$D,B28,Expenses!$C:$C,$B$21) -> 0 | D28: =SUMIFS(Expenses!$G:$G,Expenses!$B:$B,$D$1,Expenses!$D:$D,B28,Expenses!$C:$C,$B$21) -> 0 | E28: =SUMIFS(Expenses!$G:$G,Expenses!$B:$B,$E$1,Expenses!$D:$D,B28,Expenses!$C:$C,$B$21) -> 0 | F28: =SUMIFS(Expenses!$G:$G,Expenses!$B:$B,$F$1,Expenses!$D:$D,B28,Expenses!$C:$C,$B$21) -> 0 | G28: =SUMIFS(Expenses!$G:$G,Expenses!$B:$B,$G$1,Expenses!$D:$D,B28,Expenses!$C:$C,$B$21) -> 0 | H28: =SUMIFS(Expenses!$G:$G,Expenses!$B:$B,$H$1,Expenses!$D:$D,B28,Expenses!$C:$C,$B$21) -> 0 | I28: =SUMIFS(Expenses!$G:$G,Expenses!$B:$B,$I$1,Expenses!$D:$D,B28,Expenses!$C:$C,$B$21) -> 0 | J28: =SUMIFS(Expenses!$G:$G,Expenses!$B:$B,$J$1,Expenses!$D:$D,B28,Expenses!$C:$C,$B$21) -> 0 | K28: =SUMIFS(Expenses!$G:$G,Expenses!$B:$B,$K$1,Expenses!$D:$D,B28,Expenses!$C:$C,$B$21) -> 0 | L28: =SUMIFS(Expenses!$G:$G,Expenses!$B:$B,$L$1,Expenses!$D:$D,B28,Expenses!$C:$C,$B$21) -> 0 | M28: =SUMIFS(Expenses!$G:$G,Expenses!$B:$B,$M$1,Expenses!$D:$D,B28,Expenses!$C:$C,$B$21) -> 0 | N28: =SUMIFS(Expenses!$G:$G,Expenses!$B:$B,$N$1,Expenses!$D:$D,B28,Expenses!$C:$C,$B$21) -> 0 | O28: =SUMIFS(Expenses!$G:$G,Expenses!$B:$B,$O$1,Expenses!$D:$D,B28,Expenses!$C:$C,$B$21) -> 0 | P28: =SUMIFS(Expenses!$G:$G,Expenses!$B:$B,$P$1,Expenses!$D:$D,B28,Expenses!$C:$C,$B$21) -> 0 | Q28: =SUMIFS(Expenses!$G:$G,Expenses!$B:$B,$Q$1,Expenses!$D:$D,B28,Expenses!$C:$C,$B$21) -> 0 | R28: =SUMIFS(Expenses!$G:$G,Expenses!$B:$B,$R$1,Expenses!$D:$D,B28,Expenses!$C:$C,$B$21) -> 0 | S28: =SUMIFS(Expenses!$G:$G,Expenses!$B:$B,$S$1,Expenses!$D:$D,B28,Expenses!$C:$C,$B$21) -> 0
A29: =SUM(C29:AA29) -> 0 | B29: Protein Purchase | C29: =SUMIFS(Expenses!$G:$G,Expenses!$B:$B,$C$1,Expenses!$D:$D,B29,Expenses!$C:$C,$B$21) -> 0 | D29: =SUMIFS(Expenses!$G:$G,Expenses!$B:$B,$D$1,Expenses!$D:$D,B29,Expenses!$C:$C,$B$21) -> 0 | E29: =SUMIFS(Expenses!$G:$G,Expenses!$B:$B,$E$1,Expenses!$D:$D,B29,Expenses!$C:$C,$B$21) -> 0 | F29: =SUMIFS(Expenses!$G:$G,Expenses!$B:$B,$F$1,Expenses!$D:$D,B29,Expenses!$C:$C,$B$21) -> 0 | G29: =SUMIFS(Expenses!$G:$G,Expenses!$B:$B,$G$1,Expenses!$D:$D,B29,Expenses!$C:$C,$B$21) -> 0 | H29: =SUMIFS(Expenses!$G:$G,Expenses!$B:$B,$H$1,Expenses!$D:$D,B29,Expenses!$C:$C,$B$21) -> 0 | I29: =SUMIFS(Expenses!$G:$G,Expenses!$B:$B,$I$1,Expenses!$D:$D,B29,Expenses!$C:$C,$B$21) -> 0 | J29: =SUMIFS(Expenses!$G:$G,Expenses!$B:$B,$J$1,Expenses!$D:$D,B29,Expenses!$C:$C,$B$21) -> 0 | K29: =SUMIFS(Expenses!$G:$G,Expenses!$B:$B,$K$1,Expenses!$D:$D,B29,Expenses!$C:$C,$B$21) -> 0 | L29: =SUMIFS(Expenses!$G:$G,Expenses!$B:$B,$L$1,Expenses!$D:$D,B29,Expenses!$C:$C,$B$21) -> 0 | M29: =SUMIFS(Expenses!$G:$G,Expenses!$B:$B,$M$1,Expenses!$D:$D,B29,Expenses!$C:$C,$B$21) -> 0 | N29: =SUMIFS(Expenses!$G:$G,Expenses!$B:$B,$N$1,Expenses!$D:$D,B29,Expenses!$C:$C,$B$21) -> 0 | O29: =SUMIFS(Expenses!$G:$G,Expenses!$B:$B,$O$1,Expenses!$D:$D,B29,Expenses!$C:$C,$B$21) -> 0 | P29: =SUMIFS(Expenses!$G:$G,Expenses!$B:$B,$P$1,Expenses!$D:$D,B29,Expenses!$C:$C,$B$21) -> 0 | Q29: =SUMIFS(Expenses!$G:$G,Expenses!$B:$B,$Q$1,Expenses!$D:$D,B29,Expenses!$C:$C,$B$21) -> 0 | R29: =SUMIFS(Expenses!$G:$G,Expenses!$B:$B,$R$1,Expenses!$D:$D,B29,Expenses!$C:$C,$B$21) -> 0 | S29: =SUMIFS(Expenses!$G:$G,Expenses!$B:$B,$S$1,Expenses!$D:$D,B29,Expenses!$C:$C,$B$21) -> 0
A30: =SUM(C30:AA30) -> 0 | B30: Studio Share | C30: =SUMIFS(Expenses!$G:$G,Expenses!$B:$B,$C$1,Expenses!$D:$D,B30,Expenses!$C:$C,$B$21) -> 0 | D30: =SUMIFS(Expenses!$G:$G,Expenses!$B:$B,$D$1,Expenses!$D:$D,B30,Expenses!$C:$C,$B$21) -> 0 | E30: =SUMIFS(Expenses!$G:$G,Expenses!$B:$B,$E$1,Expenses!$D:$D,B30,Expenses!$C:$C,$B$21) -> 0 | F30: =SUMIFS(Expenses!$G:$G,Expenses!$B:$B,$F$1,Expenses!$D:$D,B30,Expenses!$C:$C,$B$21) -> 0 | G30: =SUMIFS(Expenses!$G:$G,Expenses!$B:$B,$G$1,Expenses!$D:$D,B30,Expenses!$C:$C,$B$21) -> 0 | H30: =SUMIFS(Expenses!$G:$G,Expenses!$B:$B,$H$1,Expenses!$D:$D,B30,Expenses!$C:$C,$B$21) -> 0 | I30: =SUMIFS(Expenses!$G:$G,Expenses!$B:$B,$I$1,Expenses!$D:$D,B30,Expenses!$C:$C,$B$21) -> 0 | J30: =SUMIFS(Expenses!$G:$G,Expenses!$B:$B,$J$1,Expenses!$D:$D,B30,Expenses!$C:$C,$B$21) -> 0 | K30: =SUMIFS(Expenses!$G:$G,Expenses!$B:$B,$K$1,Expenses!$D:$D,B30,Expenses!$C:$C,$B$21) -> 0 | L30: =SUMIFS(Expenses!$G:$G,Expenses!$B:$B,$L$1,Expenses!$D:$D,B30,Expenses!$C:$C,$B$21) -> 0 | M30: =SUMIFS(Expenses!$G:$G,Expenses!$B:$B,$M$1,Expenses!$D:$D,B30,Expenses!$C:$C,$B$21) -> 0 | N30: =SUMIFS(Expenses!$G:$G,Expenses!$B:$B,$N$1,Expenses!$D:$D,B30,Expenses!$C:$C,$B$21) -> 0 | O30: =SUMIFS(Expenses!$G:$G,Expenses!$B:$B,$O$1,Expenses!$D:$D,B30,Expenses!$C:$C,$B$21) -> 0 | P30: =SUMIFS(Expenses!$G:$G,Expenses!$B:$B,$P$1,Expenses!$D:$D,B30,Expenses!$C:$C,$B$21) -> 0 | Q30: =SUMIFS(Expenses!$G:$G,Expenses!$B:$B,$Q$1,Expenses!$D:$D,B30,Expenses!$C:$C,$B$21) -> 0 | R30: =SUMIFS(Expenses!$G:$G,Expenses!$B:$B,$R$1,Expenses!$D:$D,B30,Expenses!$C:$C,$B$21) -> 0 | S30: =SUMIFS(Expenses!$G:$G,Expenses!$B:$B,$S$1,Expenses!$D:$D,B30,Expenses!$C:$C,$B$21) -> 0
A31: =SUM(C31:AA31) -> 0 | B31: PT Share | C31: =SUMIFS(Expenses!$G:$G,Expenses!$B:$B,$C$1,Expenses!$D:$D,B31,Expenses!$C:$C,$B$21) -> 0 | D31: =SUMIFS(Expenses!$G:$G,Expenses!$B:$B,$D$1,Expenses!$D:$D,B31,Expenses!$C:$C,$B$21) -> 0 | E31: =SUMIFS(Expenses!$G:$G,Expenses!$B:$B,$E$1,Expenses!$D:$D,B31,Expenses!$C:$C,$B$21) -> 0 | F31: =SUMIFS(Expenses!$G:$G,Expenses!$B:$B,$F$1,Expenses!$D:$D,B31,Expenses!$C:$C,$B$21) -> 0 | G31: =SUMIFS(Expenses!$G:$G,Expenses!$B:$B,$G$1,Expenses!$D:$D,B31,Expenses!$C:$C,$B$21) -> 0 | H31: =SUMIFS(Expenses!$G:$G,Expenses!$B:$B,$H$1,Expenses!$D:$D,B31,Expenses!$C:$C,$B$21) -> 0 | I31: =SUMIFS(Expenses!$G:$G,Expenses!$B:$B,$I$1,Expenses!$D:$D,B31,Expenses!$C:$C,$B$21) -> 0 | J31: =SUMIFS(Expenses!$G:$G,Expenses!$B:$B,$J$1,Expenses!$D:$D,B31,Expenses!$C:$C,$B$21) -> 0 | K31: =SUMIFS(Expenses!$G:$G,Expenses!$B:$B,$K$1,Expenses!$D:$D,B31,Expenses!$C:$C,$B$21) -> 0 | L31: =SUMIFS(Expenses!$G:$G,Expenses!$B:$B,$L$1,Expenses!$D:$D,B31,Expenses!$C:$C,$B$21) -> 0 | M31: =SUMIFS(Expenses!$G:$G,Expenses!$B:$B,$M$1,Expenses!$D:$D,B31,Expenses!$C:$C,$B$21) -> 0 | N31: =SUMIFS(Expenses!$G:$G,Expenses!$B:$B,$N$1,Expenses!$D:$D,B31,Expenses!$C:$C,$B$21) -> 0 | O31: =SUMIFS(Expenses!$G:$G,Expenses!$B:$B,$O$1,Expenses!$D:$D,B31,Expenses!$C:$C,$B$21) -> 0 | P31: =SUMIFS(Expenses!$G:$G,Expenses!$B:$B,$P$1,Expenses!$D:$D,B31,Expenses!$C:$C,$B$21) -> 0 | Q31: =SUMIFS(Expenses!$G:$G,Expenses!$B:$B,$Q$1,Expenses!$D:$D,B31,Expenses!$C:$C,$B$21) -> 0 | R31: =SUMIFS(Expenses!$G:$G,Expenses!$B:$B,$R$1,Expenses!$D:$D,B31,Expenses!$C:$C,$B$21) -> 0 | S31: =SUMIFS(Expenses!$G:$G,Expenses!$B:$B,$S$1,Expenses!$D:$D,B31,Expenses!$C:$C,$B$21) -> 0
A32: =SUM(C32:AA32) -> 0 | B32: Misc | C32: =SUMIFS(Expenses!$G:$G,Expenses!$B:$B,$C$1,Expenses!$D:$D,B32,Expenses!$C:$C,$B$21) -> 0 | D32: =SUMIFS(Expenses!$G:$G,Expenses!$B:$B,$D$1,Expenses!$D:$D,B32,Expenses!$C:$C,$B$21) -> 0 | E32: =SUMIFS(Expenses!$G:$G,Expenses!$B:$B,$E$1,Expenses!$D:$D,B32,Expenses!$C:$C,$B$21) -> 0 | F32: =SUMIFS(Expenses!$G:$G,Expenses!$B:$B,$F$1,Expenses!$D:$D,B32,Expenses!$C:$C,$B$21) -> 0 | G32: =SUMIFS(Expenses!$G:$G,Expenses!$B:$B,$G$1,Expenses!$D:$D,B32,Expenses!$C:$C,$B$21) -> 0 | H32: =SUMIFS(Expenses!$G:$G,Expenses!$B:$B,$H$1,Expenses!$D:$D,B32,Expenses!$C:$C,$B$21) -> 0 | I32: =SUMIFS(Expenses!$G:$G,Expenses!$B:$B,$I$1,Expenses!$D:$D,B32,Expenses!$C:$C,$B$21) -> 0 | J32: =SUMIFS(Expenses!$G:$G,Expenses!$B:$B,$J$1,Expenses!$D:$D,B32,Expenses!$C:$C,$B$21) -> 0 | K32: =SUMIFS(Expenses!$G:$G,Expenses!$B:$B,$K$1,Expenses!$D:$D,B32,Expenses!$C:$C,$B$21) -> 0 | L32: =SUMIFS(Expenses!$G:$G,Expenses!$B:$B,$L$1,Expenses!$D:$D,B32,Expenses!$C:$C,$B$21) -> 0 | M32: =SUMIFS(Expenses!$G:$G,Expenses!$B:$B,$M$1,Expenses!$D:$D,B32,Expenses!$C:$C,$B$21) -> 0 | N32: =SUMIFS(Expenses!$G:$G,Expenses!$B:$B,$N$1,Expenses!$D:$D,B32,Expenses!$C:$C,$B$21) -> 0 | O32: =SUMIFS(Expenses!$G:$G,Expenses!$B:$B,$O$1,Expenses!$D:$D,B32,Expenses!$C:$C,$B$21) -> 0 | P32: =SUMIFS(Expenses!$G:$G,Expenses!$B:$B,$P$1,Expenses!$D:$D,B32,Expenses!$C:$C,$B$21) -> 0 | Q32: =SUMIFS(Expenses!$G:$G,Expenses!$B:$B,$Q$1,Expenses!$D:$D,B32,Expenses!$C:$C,$B$21) -> 0 | R32: =SUMIFS(Expenses!$G:$G,Expenses!$B:$B,$R$1,Expenses!$D:$D,B32,Expenses!$C:$C,$B$21) -> 0 | S32: =SUMIFS(Expenses!$G:$G,Expenses!$B:$B,$S$1,Expenses!$D:$D,B32,Expenses!$C:$C,$B$21) -> 0
A33: =SUM(C33:AA33) -> 0 | B33: Sales Tax | C33: =SUMIFS(Expenses!$G:$G,Expenses!$B:$B,$C$1,Expenses!$D:$D,B33,Expenses!$C:$C,$B$21) -> 0 | D33: =SUMIFS(Expenses!$G:$G,Expenses!$B:$B,$D$1,Expenses!$D:$D,B33,Expenses!$C:$C,$B$21) -> 0 | E33: =SUMIFS(Expenses!$G:$G,Expenses!$B:$B,$E$1,Expenses!$D:$D,B33,Expenses!$C:$C,$B$21) -> 0 | F33: =SUMIFS(Expenses!$G:$G,Expenses!$B:$B,$F$1,Expenses!$D:$D,B33,Expenses!$C:$C,$B$21) -> 0 | G33: =SUMIFS(Expenses!$G:$G,Expenses!$B:$B,$G$1,Expenses!$D:$D,B33,Expenses!$C:$C,$B$21) -> 0 | H33: =SUMIFS(Expenses!$G:$G,Expenses!$B:$B,$H$1,Expenses!$D:$D,B33,Expenses!$C:$C,$B$21) -> 0 | I33: =SUMIFS(Expenses!$G:$G,Expenses!$B:$B,$I$1,Expenses!$D:$D,B33,Expenses!$C:$C,$B$21) -> 0 | J33: =SUMIFS(Expenses!$G:$G,Expenses!$B:$B,$J$1,Expenses!$D:$D,B33,Expenses!$C:$C,$B$21) -> 0 | K33: =SUMIFS(Expenses!$G:$G,Expenses!$B:$B,$K$1,Expenses!$D:$D,B33,Expenses!$C:$C,$B$21) -> 0 | L33: =SUMIFS(Expenses!$G:$G,Expenses!$B:$B,$L$1,Expenses!$D:$D,B33,Expenses!$C:$C,$B$21) -> 0 | M33: =SUMIFS(Expenses!$G:$G,Expenses!$B:$B,$M$1,Expenses!$D:$D,B33,Expenses!$C:$C,$B$21) -> 0 | N33: =SUMIFS(Expenses!$G:$G,Expenses!$B:$B,$N$1,Expenses!$D:$D,B33,Expenses!$C:$C,$B$21) -> 0 | O33: =SUMIFS(Expenses!$G:$G,Expenses!$B:$B,$O$1,Expenses!$D:$D,B33,Expenses!$C:$C,$B$21) -> 0 | P33: =SUMIFS(Expenses!$G:$G,Expenses!$B:$B,$P$1,Expenses!$D:$D,B33,Expenses!$C:$C,$B$21) -> 0 | Q33: =SUMIFS(Expenses!$G:$G,Expenses!$B:$B,$Q$1,Expenses!$D:$D,B33,Expenses!$C:$C,$B$21) -> 0 | R33: =SUMIFS(Expenses!$G:$G,Expenses!$B:$B,$R$1,Expenses!$D:$D,B33,Expenses!$C:$C,$B$21) -> 0 | S33: =SUMIFS(Expenses!$G:$G,Expenses!$B:$B,$S$1,Expenses!$D:$D,B33,Expenses!$C:$C,$B$21) -> 0
A34: =SUM(C34:AA34) -> 0 | B34: Legal Professional Charges | C34: =SUMIFS(Expenses!$G:$G,Expenses!$B:$B,$C$1,Expenses!$D:$D,B34,Expenses!$C:$C,$B$21) -> 0 | D34: =SUMIFS(Expenses!$G:$G,Expenses!$B:$B,$D$1,Expenses!$D:$D,B34,Expenses!$C:$C,$B$21) -> 0 | E34: =SUMIFS(Expenses!$G:$G,Expenses!$B:$B,$E$1,Expenses!$D:$D,B34,Expenses!$C:$C,$B$21) -> 0 | F34: =SUMIFS(Expenses!$G:$G,Expenses!$B:$B,$F$1,Expenses!$D:$D,B34,Expenses!$C:$C,$B$21) -> 0 | G34: =SUMIFS(Expenses!$G:$G,Expenses!$B:$B,$G$1,Expenses!$D:$D,B34,Expenses!$C:$C,$B$21) -> 0 | H34: =SUMIFS(Expenses!$G:$G,Expenses!$B:$B,$H$1,Expenses!$D:$D,B34,Expenses!$C:$C,$B$21) -> 0 | I34: =SUMIFS(Expenses!$G:$G,Expenses!$B:$B,$I$1,Expenses!$D:$D,B34,Expenses!$C:$C,$B$21) -> 0 | J34: =SUMIFS(Expenses!$G:$G,Expenses!$B:$B,$J$1,Expenses!$D:$D,B34,Expenses!$C:$C,$B$21) -> 0 | K34: =SUMIFS(Expenses!$G:$G,Expenses!$B:$B,$K$1,Expenses!$D:$D,B34,Expenses!$C:$C,$B$21) -> 0 | L34: =SUMIFS(Expenses!$G:$G,Expenses!$B:$B,$L$1,Expenses!$D:$D,B34,Expenses!$C:$C,$B$21) -> 0 | M34: =SUMIFS(Expenses!$G:$G,Expenses!$B:$B,$M$1,Expenses!$D:$D,B34,Expenses!$C:$C,$B$21) -> 0 | N34: =SUMIFS(Expenses!$G:$G,Expenses!$B:$B,$N$1,Expenses!$D:$D,B34,Expenses!$C:$C,$B$21) -> 0 | O34: =SUMIFS(Expenses!$G:$G,Expenses!$B:$B,$O$1,Expenses!$D:$D,B34,Expenses!$C:$C,$B$21) -> 0 | P34: =SUMIFS(Expenses!$G:$G,Expenses!$B:$B,$P$1,Expenses!$D:$D,B34,Expenses!$C:$C,$B$21) -> 0 | Q34: =SUMIFS(Expenses!$G:$G,Expenses!$B:$B,$Q$1,Expenses!$D:$D,B34,Expenses!$C:$C,$B$21) -> 0 | R34: =SUMIFS(Expenses!$G:$G,Expenses!$B:$B,$R$1,Expenses!$D:$D,B34,Expenses!$C:$C,$B$21) -> 0 | S34: =SUMIFS(Expenses!$G:$G,Expenses!$B:$B,$S$1,Expenses!$D:$D,B34,Expenses!$C:$C,$B$21) -> 0
A35: =SUM(A22:A34) -> 0 | B35: TOTAL | C35: =SUM(C22:C34) -> 0 | D35: =SUM(D22:D34) -> 0 | E35: =SUM(E22:E34) -> 0 | F35: =SUM(F22:F34) -> 0 | G35: =SUM(G22:G34) -> 0 | H35: =SUM(H22:H34) -> 0 | I35: =SUM(I22:I34) -> 0 | J35: =SUM(J22:J34) -> 0 | ... S35: =SUM(S22:S34) -> 0
A37: =SUM(C37:S37) -> 3240250 | B37: GRAND TOTAL | C37: =C19+C35 -> 200000 | D37: =D19+D35 -> 350000 | E37: =E19+E35 -> 551054 | F37: =F19+F35 -> 300900 | G37: =G19+G35 -> 65000 | H37: =H19+H35 -> 266809 | I37: =I19+I35 -> 166237 | J37: =J19+J35 -> 0 | ... S37: =S19+S35 -> 0
B39: Sale | C39: =SUMIF('XCAL Clients Feeded'!$F:$F,'Expense Breakup'!C21,'XCAL Clients Feeded'!$J:$J) -> 0 | D39: =SUMIF('XCAL Clients Feeded'!$F:$F,'Expense Breakup'!D21,'XCAL Clients Feeded'!$J:$J) -> 0 | E39: =SUMIF('XCAL Clients Feeded'!$F:$F,'Expense Breakup'!E21,'XCAL Clients Feeded'!$J:$J) -> 0 | F39: =SUMIF('XCAL Clients Feeded'!$F:$F,'Expense Breakup'!F21,'XCAL Clients Feeded'!$J:$J) -> 0 | G39: =SUMIF('XCAL Clients Feeded'!$F:$F,'Expense Breakup'!G21,'XCAL Clients Feeded'!$J:$J) -> 0 | H39: =SUMIF('XCAL Clients Feeded'!$F:$F,'Expense Breakup'!H21,'XCAL Clients Feeded'!$J:$J) -> 0 | I39: =SUMIF('XCAL Clients Feeded'!$F:$F,'Expense Breakup'!I21,'XCAL Clients Feeded'!$J:$J) -> 0 | J39: =SUMIF('XCAL Clients Feeded'!$F:$F,'Expense Breakup'!J21,'XCAL Clients Feeded'!$J:$J) -> 98000 | ... S39: =SUMIF('XCAL Clients Feeded'!$F:$F,'Expense Breakup'!S21,'XCAL Clients Feeded'!$J:$J) -> 0
B40: Expense | C40: =C37 -> 200000 | D40: =D37 -> 350000 | E40: =E37 -> 551054 | F40: =F37 -> 300900 | G40: =G37 -> 65000 | H40: =H37 -> 266809 | I40: =I37 -> 166237 | J40: =J37 -> 0 | ... S40: =S37 -> 0
